Workbook
Name CombinationNames: ΣυνδΑθρ!$A$2:INDEX(ΣυνδΑθρ!$A:$A,MATCH(0,ΣυνδΑθρ!$A$2:$A$100,0))
Name CombinationNamesSorted: OFFSET(Ref!$F$1,1,0,COUNTIF(ΣυνδΑθρ!$A:$A,"?*")-1,1)
Name ItemNames: OFFSET(Ref!$D$1,1,0,MAX(Υλικά!$A:$A),1)
Name ItemNamesSorted: OFFSET(Ref!$E$1,1,0,MAX(Υλικά!$A:$A),1)

Sheet Ref
B1: Kcal/gr | D1: Υλικά | E1: Υλικά Sorted | F1: Συνδυασμοί Sorted
A2: Protein | B2: 4 | D2: =IFERROR(INDEX(Υλικά!$B$2:$B$140,MATCH(ROW()-ROW($D$1),Υλικά!$A$2:$A$140,0)),"") -> Μελιτζάνες | E2: {=IF(COUNTA(ItemNames)>=ROWS($E$1:E1),INDEX(ItemNames,MATCH(SMALL(COUNTIF(ItemNames,"<"&ItemNames),ROW(E1)),COUNTIF(ItemNames,"<"&ItemNames),0)),"")} -> Bresaola Negroni | F2: {=IF(COUNTA(CombinationNames)>=ROWS($F$1:F1),INDEX(CombinationNames,MATCH(SMALL(COUNTIF(CombinationNames,"<"&CombinationNames),ROW(F1)),COUNTIF(CombinationNames,"<"&CombinationNames),0)),"")} -> Banana bread
A3: Carb | B3: 4 | D3: =IFERROR(INDEX(Υλικά!$B$2:$B$140,MATCH(ROW()-ROW($D$1),Υλικά!$A$2:$A$140,0)),"") -> Κρεμμύδι | E3: {=IF(COUNTA(ItemNames)>=ROWS($E$1:E2),INDEX(ItemNames,MATCH(SMALL(COUNTIF(ItemNames,"<"&ItemNames),ROW(E2)),COUNTIF(ItemNames,"<"&ItemNames),0)),"")} -> Cottage Cheese AB | F3: {=IF(COUNTA(CombinationNames)>=ROWS($F$1:F2),INDEX(CombinationNames,MATCH(SMALL(COUNTIF(CombinationNames,"<"&CombinationNames),ROW(F2)),COUNTIF(CombinationNames,"<"&CombinationNames),0)),"")} -> Carrot Cake Κολοβέρου
A4: Fat | B4: 9 | D4: =IFERROR(INDEX(Υλικά!$B$2:$B$140,MATCH(ROW()-ROW($D$1),Υλικά!$A$2:$A$140,0)),"") -> Ελαιόλαδο | E4: {=IF(COUNTA(ItemNames)>=ROWS($E$1:E3),INDEX(ItemNames,MATCH(SMALL(COUNTIF(ItemNames,"<"&ItemNames),ROW(E3)),COUNTIF(ItemNames,"<"&ItemNames),0)),"")} -> Lays Crackers Πολύσπορα | F4: {=IF(COUNTA(CombinationNames)>=ROWS($F$1:F3),INDEX(CombinationNames,MATCH(SMALL(COUNTIF(CombinationNames,"<"&CombinationNames),ROW(F3)),COUNTIF(CombinationNames,"<"&CombinationNames),0)),"")} -> Αγκινάρες με Κουκιά
D5: =IFERROR(INDEX(Υλικά!$B$2:$B$140,MATCH(ROW()-ROW($D$1),Υλικά!$A$2:$A$140,0)),"") -> Ρύζι parboiled | E5: {=IF(COUNTA(ItemNames)>=ROWS($E$1:E4),INDEX(ItemNames,MATCH(SMALL(COUNTIF(ItemNames,"<"&ItemNames),ROW(E4)),COUNTIF(ItemNames,"<"&ItemNames),0)),"")} -> Αγγούρι | F5: {=IF(COUNTA(CombinationNames)>=ROWS($F$1:F4),INDEX(CombinationNames,MATCH(SMALL(COUNTIF(CombinationNames,"<"&CombinationNames),ROW(F4)),COUNTIF(CombinationNames,"<"&CombinationNames),0)),"")} -> Αρακάς Αντώνη
D6: =IFERROR(INDEX(Υλικά!$B$2:$B$140,MATCH(ROW()-ROW($D$1),Υλικά!$A$2:$A$140,0)),"") -> Ντομάτα κονκασέ | E6: {=IF(COUNTA(ItemNames)>=ROWS($E$1:E5),INDEX(ItemNames,MATCH(SMALL(COUNTIF(ItemNames,"<"&ItemNames),ROW(E5)),COUNTIF(ItemNames,"<"&ItemNames),0)),"")} -> Αγκινάρες | F6: {=IF(COUNTA(CombinationNames)>=ROWS($F$1:F5),INDEX(CombinationNames,MATCH(SMALL(COUNTIF(CombinationNames,"<"&CombinationNames),ROW(F5)),COUNTIF(CombinationNames,"<"&CombinationNames),0)),"")} -> Αρακάς Τατιάνας
D7: =IFERROR(INDEX(Υλικά!$B$2:$B$140,MATCH(ROW()-ROW($D$1),Υλικά!$A$2:$A$140,0)),"") -> Πιπεριές | E7: {=IF(COUNTA(ItemNames)>=ROWS($E$1:E6),INDEX(ItemNames,MATCH(SMALL(COUNTIF(ItemNames,"<"&ItemNames),ROW(E6)),COUNTIF(ItemNames,"<"&ItemNames),0)),"")} -> Ακτινίδιο | F7: {=IF(COUNTA(CombinationNames)>=ROWS($F$1:F6),INDEX(CombinationNames,MATCH(SMALL(COUNTIF(CombinationNames,"<"&CombinationNames),ROW(F6)),COUNTIF(CombinationNames,"<"&CombinationNames),0)),"")} -> Βραδινό γιαούρτι-φρούτα
D8: =IFERROR(INDEX(Υλικά!$B$2:$B$140,MATCH(ROW()-ROW($D$1),Υλικά!$A$2:$A$140,0)),"") -> Γαλοπούλα Καπνιστή CretaFarm | E8: {=IF(COUNTA(ItemNames)>=ROWS($E$1:E7),INDEX(ItemNames,MATCH(SMALL(COUNTIF(ItemNames,"<"&ItemNames),ROW(E7)),COUNTIF(ItemNames,"<"&ItemNames),0)),"")} -> Αλεύρι ΓΟΧ Μύλοι Αγ. Γεωργίου | F8: {=IF(COUNTA(CombinationNames)>=ROWS($F$1:F7),INDEX(CombinationNames,MATCH(SMALL(COUNTIF(CombinationNames,"<"&CombinationNames),ROW(F7)),COUNTIF(CombinationNames,"<"&CombinationNames),0)),"")} -> Γαύρος Αλέκου
D9: =IFERROR(INDEX(Υλικά!$B$2:$B$140,MATCH(ROW()-ROW($D$1),Υλικά!$A$2:$A$140,0)),"") -> Κασέρι Ελασσόνας ΑΒ | E9: {=IF(COUNTA(ItemNames)>=ROWS($E$1:E8),INDEX(ItemNames,MATCH(SMALL(COUNTIF(ItemNames,"<"&ItemNames),ROW(E8)),COUNTIF(ItemNames,"<"&ItemNames),0)),"")} -> Αλεύρι Καλαμποκιού | F9: {=IF(COUNTA(CombinationNames)>=ROWS($F$1:F8),INDEX(CombinationNames,MATCH(SMALL(COUNTIF(CombinationNames,"<"&CombinationNames),ROW(F8)),COUNTIF(CombinationNames,"<"&CombinationNames),0)),"")} -> Γλυκόξινο Κοτόπουλο
D10: =IFERROR(INDEX(Υλικά!$B$2:$B$140,MATCH(ROW()-ROW($D$1),Υλικά!$A$2:$A$140,0)),"") -> Ψωμί Χωριανό με Σίκαλη | E10: {=IF(COUNTA(ItemNames)>=ROWS($E$1:E9),INDEX(ItemNames,MATCH(SMALL(COUNTIF(ItemNames,"<"&ItemNames),ROW(E9)),COUNTIF(ItemNames,"<"&ItemNames),0)),"")} -> Αλεύρι Ολικής Αλλατίνη | F10: {=IF(COUNTA(CombinationNames)>=ROWS($F$1:F9),INDEX(CombinationNames,MATCH(SMALL(COUNTIF(CombinationNames,"<"&CombinationNames),ROW(F9)),COUNTIF(CombinationNames,"<"&CombinationNames),0)),"")} -> Κάρυ Λαχανικών Γαλοπούλα
D11: =IFERROR(INDEX(Υλικά!$B$2:$B$140,MATCH(ROW()-ROW($D$1),Υλικά!$A$2:$A$140,0)),"") -> Ψωμί Γερμανικού Τύπου Κατσέλη | E11: {=IF(COUNTA(ItemNames)>=ROWS($E$1:E10),INDEX(ItemNames,MATCH(SMALL(COUNTIF(ItemNames,"<"&ItemNames),ROW(E10)),COUNTIF(ItemNames,"<"&ItemNames),0)),"")} -> Αμύγδαλα | F11: {=IF(COUNTA(CombinationNames)>=ROWS($F$1:F10),INDEX(CombinationNames,MATCH(SMALL(COUNTIF(CombinationNames,"<"&CombinationNames),ROW(F10)),COUNTIF(CombinationNames,"<"&CombinationNames),0)),"")} -> Κιμάς Μακαρονιών
D12: =IFERROR(INDEX(Υλικά!$B$2:$B$140,MATCH(ROW()-ROW($D$1),Υλικά!$A$2:$A$140,0)),"") -> Αυγά | E12: {=IF(COUNTA(ItemNames)>=ROWS($E$1:E11),INDEX(ItemNames,MATCH(SMALL(COUNTIF(ItemNames,"<"&ItemNames),ROW(E11)),COUNTIF(ItemNames,"<"&ItemNames),0)),"")} -> Αμύγδαλα Λευκά | F12: {=IF(COUNTA(CombinationNames)>=ROWS($F$1:F11),INDEX(CombinationNames,MATCH(SMALL(COUNTIF(CombinationNames,"<"&CombinationNames),ROW(F11)),COUNTIF(CombinationNames,"<"&CombinationNames),0)),"")} -> Κολοκύθια-Πατάτες
D13: =IFERROR(INDEX(Υλικά!$B$2:$B$140,MATCH(ROW()-ROW($D$1),Υλικά!$A$2:$A$140,0)),"") -> Γάλα Όλυμπος 1.5% | E13: {=IF(COUNTA(ItemNames)>=ROWS($E$1:E12),INDEX(ItemNames,MATCH(SMALL(COUNTIF(ItemNames,"<"&ItemNames),ROW(E12)),COUNTIF(ItemNames,"<"&ItemNames),0)),"")} -> Ανανάς Κονσέρβα σε Χυμό Del Monde | F13: {=IF(COUNTA(CombinationNames)>=ROWS($F$1:F12),INDEX(CombinationNames,MATCH(SMALL(COUNTIF(CombinationNames,"<"&CombinationNames),ROW(F12)),COUNTIF(CombinationNames,"<"&CombinationNames),0)),"")} -> Κολοκυθόσουπα
D14: =IFERROR(INDEX(Υλικά!$B$2:$B$140,MATCH(ROW()-ROW($D$1),Υλικά!$A$2:$A$140,0)),"") -> Τόνος σε Ηλιέλαιο 365 200g | E14: {=IF(COUNTA(ItemNames)>=ROWS($E$1:E13),INDEX(ItemNames,MATCH(SMALL(COUNTIF(ItemNames,"<"&ItemNames),ROW(E13)),COUNTIF(ItemNames,"<"&ItemNames),0)),"")} -> Ανθότυρο Μπουτσώλης Αμφιλοχίας | F14: {=IF(COUNTA(CombinationNames)>=ROWS($F$1:F13),INDEX(CombinationNames,MATCH(SMALL(COUNTIF(CombinationNames,"<"&CombinationNames),ROW(F13)),COUNTIF(CombinationNames,"<"&CombinationNames),0)),"")} -> Κοτόπουλο Κοκκινιστό
D15: =IFERROR(INDEX(Υλικά!$B$2:$B$140,MATCH(ROW()-ROW($D$1),Υλικά!$A$2:$A$140,0)),"") -> Γιαούρτι Όλυμπος 2% | E15: {=IF(COUNTA(ItemNames)>=ROWS($E$1:E14),INDEX(ItemNames,MATCH(SMALL(COUNTIF(ItemNames,"<"&ItemNames),ROW(E14)),COUNTIF(ItemNames,"<"&ItemNames),0)),"")} -> ΑξιαγάΠιτες | F15: {=IF(COUNTA(CombinationNames)>=ROWS($F$1:F14),INDEX(CombinationNames,MATCH(SMALL(COUNTIF(CombinationNames,"<"&CombinationNames),ROW(F14)),COUNTIF(CombinationNames,"<"&CombinationNames),0)),"")} -> Κοτόπουλο Κόρμα
D16: =IFERROR(INDEX(Υλικά!$B$2:$B$140,MATCH(ROW()-ROW($D$1),Υλικά!$A$2:$A$140,0)),"") -> Ζάχαρη | E16: {=IF(COUNTA(ItemNames)>=ROWS($E$1:E15),INDEX(ItemNames,MATCH(SMALL(COUNTIF(ItemNames,"<"&ItemNames),ROW(E15)),COUNTIF(ItemNames,"<"&ItemNames),0)),"")} -> Απάκι ΑΒ | F16: {=IF(COUNTA(CombinationNames)>=ROWS($F$1:F15),INDEX(CombinationNames,MATCH(SMALL(COUNTIF(CombinationNames,"<"&CombinationNames),ROW(F15)),COUNTIF(CombinationNames,"<"&CombinationNames),0)),"")} -> Κοτόπουλο Λαχανικά
... D101: =IFERROR(INDEX(Υλικά!$B$2:$B$140,MATCH(ROW()-ROW($D$1),Υλικά!$A$2:$A$140,0)),"") -> Λουκάνικα Μετσόβου ΑΒ | E101: {=IF(COUNTA(ItemNames)>=ROWS($E$1:E100),INDEX(ItemNames,MATCH(SMALL(COUNTIF(ItemNames,"<"&ItemNames),ROW(E100)),COUNTIF(ItemNames,"<"&ItemNames),0)),"")} -> Πέρκα Καλλιμάνη | F101: {=IF(COUNTA(CombinationNames)>=ROWS($F$1:F100),INDEX(CombinationNames,MATCH(SMALL(COUNTIF(CombinationNames,"<"&CombinationNames),ROW(F100)),COUNTIF(CombinationNames,"<"&CombinationNames),0)),"")}
D102: =IFERROR(INDEX(Υλικά!$B$2:$B$140,MATCH(ROW()-ROW($D$1),Υλικά!$A$2:$A$140,0)),"") -> Λουκάνικα Χωριάτικα Creta Farms | E102: {=IF(COUNTA(ItemNames)>=ROWS($E$1:E101),INDEX(ItemNames,MATCH(SMALL(COUNTIF(ItemNames,"<"&ItemNames),ROW(E101)),COUNTIF(ItemNames,"<"&ItemNames),0)),"")} -> Πιπεριές
D103: =IFERROR(INDEX(Υλικά!$B$2:$B$140,MATCH(ROW()-ROW($D$1),Υλικά!$A$2:$A$140,0)),"") -> Τυρί Arla Protein Delite 5% | E103: {=IF(COUNTA(ItemNames)>=ROWS($E$1:E102),INDEX(ItemNames,MATCH(SMALL(COUNTIF(ItemNames,"<"&ItemNames),ROW(E102)),COUNTIF(ItemNames,"<"&ItemNames),0)),"")} -> Πίτα Καραμολέγκος Αξιαγάπητη
D104: =IFERROR(INDEX(Υλικά!$B$2:$B$140,MATCH(ROW()-ROW($D$1),Υλικά!$A$2:$A$140,0)),"") -> Φασόλες | E104: {=IF(COUNTA(ItemNames)>=ROWS($E$1:E103),INDEX(ItemNames,MATCH(SMALL(COUNTIF(ItemNames,"<"&ItemNames),ROW(E103)),COUNTIF(ItemNames,"<"&ItemNames),0)),"")} -> Πίτσα Τζάιαντ Χαμόν Μανιτάρια
D105: =IFERROR(INDEX(Υλικά!$B$2:$B$140,MATCH(ROW()-ROW($D$1),Υλικά!$A$2:$A$140,0)),"") -> Γαλοπούλα Πασσιάς Κορυφαίο | E105: {=IF(COUNTA(ItemNames)>=ROWS($E$1:E104),INDEX(ItemNames,MATCH(SMALL(COUNTIF(ItemNames,"<"&ItemNames),ROW(E104)),COUNTIF(ItemNames,"<"&ItemNames),0)),"")} -> Πληγούρι Fytro
D106: =IFERROR(INDEX(Υλικά!$B$2:$B$140,MATCH(ROW()-ROW($D$1),Υλικά!$A$2:$A$140,0)),"") -> Χταπόδι | E106: {=IF(COUNTA(ItemNames)>=ROWS($E$1:E105),INDEX(ItemNames,MATCH(SMALL(COUNTIF(ItemNames,"<"&ItemNames),ROW(E105)),COUNTIF(ItemNames,"<"&ItemNames),0)),"")} -> Πορτοκάλι
D107: =IFERROR(INDEX(Υλικά!$B$2:$B$140,MATCH(ROW()-ROW($D$1),Υλικά!$A$2:$A$140,0)),"") -> Τραχανάς Χιώτικο Κελλάρι | E107: {=IF(COUNTA(ItemNames)>=ROWS($E$1:E106),INDEX(ItemNames,MATCH(SMALL(COUNTIF(ItemNames,"<"&ItemNames),ROW(E106)),COUNTIF(ItemNames,"<"&ItemNames),0)),"")} -> Ποτό 40%
D108: =IFERROR(INDEX(Υλικά!$B$2:$B$140,MATCH(ROW()-ROW($D$1),Υλικά!$A$2:$A$140,0)),"") -> Αμύγδαλα | E108: {=IF(COUNTA(ItemNames)>=ROWS($E$1:E107),INDEX(ItemNames,MATCH(SMALL(COUNTIF(ItemNames,"<"&ItemNames),ROW(E107)),COUNTIF(ItemNames,"<"&ItemNames),0)),"")} -> Πράσο
D109: =IFERROR(INDEX(Υλικά!$B$2:$B$140,MATCH(ROW()-ROW($D$1),Υλικά!$A$2:$A$140,0)),"") -> Ρεβύθια | E109: {=IF(COUNTA(ItemNames)>=ROWS($E$1:E108),INDEX(ItemNames,MATCH(SMALL(COUNTIF(ItemNames,"<"&ItemNames),ROW(E108)),COUNTIF(ItemNames,"<"&ItemNames),0)),"")} -> Ρεβύθια
D110: =IFERROR(INDEX(Υλικά!$B$2:$B$140,MATCH(ROW()-ROW($D$1),Υλικά!$A$2:$A$140,0)),"") -> Χορτόπιτα Κρητών Άρτος | E110: {=IF(COUNTA(ItemNames)>=ROWS($E$1:E109),INDEX(ItemNames,MATCH(SMALL(COUNTIF(ItemNames,"<"&ItemNames),ROW(E109)),COUNTIF(ItemNames,"<"&ItemNames),0)),"")} -> Ροδάκινο
D111: =IFERROR(INDEX(Υλικά!$B$2:$B$140,MATCH(ROW()-ROW($D$1),Υλικά!$A$2:$A$140,0)),"") -> Φαγκρί | E111: {=IF(COUNTA(ItemNames)>=ROWS($E$1:E110),INDEX(ItemNames,MATCH(SMALL(COUNTIF(ItemNames,"<"&ItemNames),ROW(E110)),COUNTIF(ItemNames,"<"&ItemNames),0)),"")} -> Ρόκα
D112: =IFERROR(INDEX(Υλικά!$B$2:$B$140,MATCH(ROW()-ROW($D$1),Υλικά!$A$2:$A$140,0)),"") -> Πατζάρι | E112: {=IF(COUNTA(ItemNames)>=ROWS($E$1:E111),INDEX(ItemNames,MATCH(SMALL(COUNTIF(ItemNames,"<"&ItemNames),ROW(E111)),COUNTIF(ItemNames,"<"&ItemNames),0)),"")} -> Ρύζι parboiled
D113: =IFERROR(INDEX(Υλικά!$B$2:$B$140,MATCH(ROW()-ROW($D$1),Υλικά!$A$2:$A$140,0)),"") -> Σκουμπρί Φλόκος Λάδι | E113: {=IF(COUNTA(ItemNames)>=ROWS($E$1:E112),INDEX(ItemNames,MATCH(SMALL(COUNTIF(ItemNames,"<"&ItemNames),ROW(E112)),COUNTIF(ItemNames,"<"&ItemNames),0)),"")} -> Σάλτσα Σόγιας
... D138: =IFERROR(INDEX(Υλικά!$B$2:$B$140,MATCH(ROW()-ROW($D$1),Υλικά!$A$2:$A$140,0)),"") -> Κεράσια | E138: {=IF(COUNTA(ItemNames)>=ROWS($E$1:E137),INDEX(ItemNames,MATCH(SMALL(COUNTIF(ItemNames,"<"&ItemNames),ROW(E137)),COUNTIF(ItemNames,"<"&ItemNames),0)),"")} -> Φάβα
D139: =IFERROR(INDEX(Υλικά!$B$2:$B$200,MATCH(ROW()-ROW($D$1),Υλικά!$A$2:$A$200,0)),"") -> Καλαμπόκι | E139: {=IF(COUNTA(ItemNames)>=ROWS($E$1:E138),INDEX(ItemNames,MATCH(SMALL(COUNTIF(ItemNames,"<"&ItemNames),ROW(E138)),COUNTIF(ItemNames,"<"&ItemNames),0)),"")} -> Φαγκρί
D140: =IFERROR(INDEX(Υλικά!$B$2:$B$200,MATCH(ROW()-ROW($D$1),Υλικά!$A$2:$A$200,0)),"") -> Ανθότυρο Μπουτσώλης Αμφιλοχίας | E140: {=IF(COUNTA(ItemNames)>=ROWS($E$1:E139),INDEX(ItemNames,MATCH(SMALL(COUNTIF(ItemNames,"<"&ItemNames),ROW(E139)),COUNTIF(ItemNames,"<"&ItemNames),0)),"")} -> Φακή
D141: =IFERROR(INDEX(Υλικά!$B$2:$B$200,MATCH(ROW()-ROW($D$1),Υλικά!$A$2:$A$200,0)),"") -> Τυρί Gouda | E141: {=IF(COUNTA(ItemNames)>=ROWS($E$1:E140),INDEX(ItemNames,MATCH(SMALL(COUNTIF(ItemNames,"<"&ItemNames),ROW(E140)),COUNTIF(ItemNames,"<"&ItemNames),0)),"")} -> Φασολάκια FROZA
D142: =IFERROR(INDEX(Υλικά!$B$2:$B$200,MATCH(ROW()-ROW($D$1),Υλικά!$A$2:$A$200,0)),"") -> Bresaola Negroni | E142: {=IF(COUNTA(ItemNames)>=ROWS($E$1:E141),INDEX(ItemNames,MATCH(SMALL(COUNTIF(ItemNames,"<"&ItemNames),ROW(E141)),COUNTIF(ItemNames,"<"&ItemNames),0)),"")} -> Φασόλες
D143: =IFERROR(INDEX(Υλικά!$B$2:$B$200,MATCH(ROW()-ROW($D$1),Υλικά!$A$2:$A$200,0)),"") -> Απάκι ΑΒ | E143: {=IF(COUNTA(ItemNames)>=ROWS($E$1:E142),INDEX(ItemNames,MATCH(SMALL(COUNTIF(ItemNames,"<"&ItemNames),ROW(E142)),COUNTIF(ItemNames,"<"&ItemNames),0)),"")} -> Φασόλια Μαυροομάτικα
D144: =IFERROR(INDEX(Υλικά!$B$2:$B$200,MATCH(ROW()-ROW($D$1),Υλικά!$A$2:$A$200,0)),"") -> Σύκα ξερά | E144: {=IF(COUNTA(ItemNames)>=ROWS($E$1:E143),INDEX(ItemNames,MATCH(SMALL(COUNTIF(ItemNames,"<"&ItemNames),ROW(E143)),COUNTIF(ItemNames,"<"&ItemNames),0)),"")} -> Φέτα
D145: =IFERROR(INDEX(Υλικά!$B$2:$B$200,MATCH(ROW()-ROW($D$1),Υλικά!$A$2:$A$200,0)),"") -> Χαλβάς Παραδοσιακός | E145: {=IF(COUNTA(ItemNames)>=ROWS($E$1:E144),INDEX(ItemNames,MATCH(SMALL(COUNTIF(ItemNames,"<"&ItemNames),ROW(E144)),COUNTIF(ItemNames,"<"&ItemNames),0)),"")} -> Φράουλες
D146: =IFERROR(INDEX(Υλικά!$B$2:$B$200,MATCH(ROW()-ROW($D$1),Υλικά!$A$2:$A$200,0)),"") -> Γιαούρτι Πρόβειο Παραδοσιακό | E146: {=IF(COUNTA(ItemNames)>=ROWS($E$1:E145),INDEX(ItemNames,MATCH(SMALL(COUNTIF(ItemNames,"<"&ItemNames),ROW(E145)),COUNTIF(ItemNames,"<"&ItemNames),0)),"")} -> Φρυγανιά Τριμμένη ΑΒ
D147: =IFERROR(INDEX(Υλικά!$B$2:$B$200,MATCH(ROW()-ROW($D$1),Υλικά!$A$2:$A$200,0)),"") -> Γαύρος Τράτα | E147: {=IF(COUNTA(ItemNames)>=ROWS($E$1:E146),INDEX(ItemNames,MATCH(SMALL(COUNTIF(ItemNames,"<"&ItemNames),ROW(E146)),COUNTIF(ItemNames,"<"&ItemNames),0)),"")} -> Φύλλο Κρούστα Χρυσή Ζύμη
D148: =IFERROR(INDEX(Υλικά!$B$2:$B$200,MATCH(ROW()-ROW($D$1),Υλικά!$A$2:$A$200,0)),"") -> Μπάμιες Κατεψυγμένες | E148: {=IF(COUNTA(ItemNames)>=ROWS($E$1:E147),INDEX(ItemNames,MATCH(SMALL(COUNTIF(ItemNames,"<"&ItemNames),ROW(E147)),COUNTIF(ItemNames,"<"&ItemNames),0)),"")} -> Φυστίκια Αιγίνης
...

Sheet Σκεύη
C1: gr
B2: Κατσαρόλα Fissler Χίου | C2: 1850
B3: Κατσαρόλι για ρύζι Χίου | C3: 1000
B4: Ελαφρύ Κατσαρόλι για ρύζι Χίου | C4: 800
B5: Κόκκινο τσουκάλι Τραυλαντώνη | C5: 1317
B6: Κόκκινο κατσαρόλι Τραυλαντώνη | C6: 800
B7: Μικρό Τσουκάλι Τομπάζη (Τατ) | C7: 1190
B8: Μεγάλο Κατσαρόλι Τομπάζη (Τατ) | C8: 1140
B9: Μικρό κατσαρόλι Τομπάζη (Τατ) | C9: 700
B10: Μεγάλο Τσουκάλι Τομπάζι (Αλ) | C10: 1390
B11: Ταψί ρηχό φούρνου (Τατ) | C11: 1230
B12: Ταψί βαθύ (Αλ) | C12: 880

Sheet Υλικά
A1: id | B1: Όνομα | C1: Κατηγορία | D1: Μονάδα | E1: Ποσότητα αναφοράς | F1: θερμίδες ονομαστικές | G1: Πρωτεΐνες g | H1: Υδατάνθρακες g | I1: Λίπη g | J1: Επιπλέον Θερμίδες | K1: Υπολογισμός Θερμίδων | L1: Διαφορά | M1: Διαφορά% | N1: Νάτριο mg | O1: Κάλιο mg
A3: =IF(B3="","",MAX(A$2:A2)+1) -> 1 | B3: Μελιτζάνες | C3: Ζαρζαβατικά | D3: gr | E3: 100 | F3: 23 | G3: 1 | H3: 5.9 | I3: 0.2 | K3: =$G3*Ref!$B$2+$H3*Ref!$B$3+$I3*Ref!$B$4+$J3 -> 29.4 | L3: =K3-F3 -> 6.4 | M3: =IF(K3>0,100*L3/K3,0) -> 21.768707
A4: =IF(B4="","",MAX(A$2:A3)+1) -> 2 | B4: Κρεμμύδι | C4: Ζαρζαβατικά | D4: gr | E4: 100 | F4: 40 | G4: 1.1 | H4: 9.3 | I4: 0.1 | K4: =$G4*Ref!$B$2+$H4*Ref!$B$3+$I4*Ref!$B$4+$J4 -> 42.5 | L4: =K4-F4 -> 2.5 | M4: =IF(K4>0,100*L4/K4,0) -> 5.8823529
A5: =IF(B5="","",MAX(A$2:A4)+1) -> 3 | B5: Ελαιόλαδο | C5: Λίπη | D5: gr | E5: 100 | F5: 800 | G5: 0 | H5: 0 | I5: 93.3 | K5: =$G5*Ref!$B$2+$H5*Ref!$B$3+$I5*Ref!$B$4+$J5 -> 839.7 | L5: =K5-F5 -> 39.7 | M5: =IF(K5>0,100*L5/K5,0) -> 4.727879
A6: =IF(B6="","",MAX(A$2:A5)+1) -> 4 | B6: Ρύζι parboiled | C6: Ζυμαρικά | D6: gr | E6: 100 | F6: 365 | G6: 7.1 | H6: 80 | I6: 0.7 | K6: =$G6*Ref!$B$2+$H6*Ref!$B$3+$I6*Ref!$B$4+$J6 -> 354.7 | L6: =K6-F6 -> -10.3 | M6: =IF(K6>0,100*L6/K6,0) -> -2.9038624
A7: =IF(B7="","",MAX(A$2:A6)+1) -> 5 | B7: Ντομάτα κονκασέ | C7: Κονσέρβες | D7: pc | E7: 1 | F7: 104 | G7: 4.8 | H7: 18.4 | I7: 0.12 | K7: =$G7*Ref!$B$2+$H7*Ref!$B$3+$I7*Ref!$B$4+$J7 -> 93.88 | L7: =K7-F7 -> -10.12 | M7: =IF(K7>0,100*L7/K7,0) -> -10.779719
A8: =IF(B8="","",MAX(A$2:A7)+1) -> 6 | B8: Πιπεριές | C8: Ζαρζαβατικά | D8: gr | E8: 100 | F8: 20 | G8: 0.9 | H8: 4.6 | I8: 0.2 | K8: =$G8*Ref!$B$2+$H8*Ref!$B$3+$I8*Ref!$B$4+$J8 -> 23.8 | L8: =K8-F8 -> 3.8 | M8: =IF(K8>0,100*L8/K8,0) -> 15.966387
A9: =IF(B9="","",MAX(A$2:A8)+1) -> 7 | B9: Γαλοπούλα Καπνιστή CretaFarm | C9: Αλλαντικά | D9: slc | E9: 1 | F9: 18 | G9: 2.8 | H9: 0.8 | I9: 0.4 | K9: =$G9*Ref!$B$2+$H9*Ref!$B$3+$I9*Ref!$B$4+$J9 -> 18 | L9: =K9-F9 -> 0 | M9: =IF(K9>0,100*L9/K9,0) -> 0
A10: =IF(B10="","",MAX(A$2:A9)+1) -> 8 | B10: Κασέρι Ελασσόνας ΑΒ | C10: Γαλακτοκομικά | D10: slc | E10: 1 | F10: 75 | G10: 5.1 | H10: 0.1 | I10: 5.6 | K10: =$G10*Ref!$B$2+$H10*Ref!$B$3+$I10*Ref!$B$4+$J10 -> 71.2 | L10: =K10-F10 -> -3.8 | M10: =IF(K10>0,100*L10/K10,0) -> -5.3370787
A11: =IF(B11="","",MAX(A$2:A10)+1) -> 9 | B11: Ψωμί Χωριανό με Σίκαλη | C11: Άλευρα | D11: slc | E11: 1 | F11: 72 | G11: 3 | H11: 11.7 | I11: 1.1 | K11: =$G11*Ref!$B$2+$H11*Ref!$B$3+$I11*Ref!$B$4+$J11 -> 68.7 | L11: =K11-F11 -> -3.3 | M11: =IF(K11>0,100*L11/K11,0) -> -4.8034934
A12: =IF(B12="","",MAX(A$2:A11)+1) -> 10 | B12: Ψωμί Γερμανικού Τύπου Κατσέλη | C12: Άλευρα | D12: slc | E12: 1 | F12: 137 | G12: 4.5 | H12: 26.1 | I12: 0.8 | K12: =$G12*Ref!$B$2+$H12*Ref!$B$3+$I12*Ref!$B$4+$J12 -> 129.6 | L12: =K12-F12 -> -7.4 | M12: =IF(K12>0,100*L12/K12,0) -> -5.7098765
A13: =IF(B13="","",MAX(A$2:A12)+1) -> 11 | B13: Αυγά | C13: Διάφορα | D13: pc | E13: 1 | F13: 93 | G13: 7.8 | H13: 0.66 | I13: 6.6 | K13: =$G13*Ref!$B$2+$H13*Ref!$B$3+$I13*Ref!$B$4+$J13 -> 93.24 | L13: =K13-F13 -> 0.24 | M13: =IF(K13>0,100*L13/K13,0) -> 0.25740026
A14: =IF(B14="","",MAX(A$2:A13)+1) -> 12 | B14: Γάλα Όλυμπος 1.5% | C14: Γαλακτοκομικά | D14: gr | E14: 100 | F14: 46 | G14: 3.3 | H14: 4.7 | I14: 1.5 | K14: =$G14*Ref!$B$2+$H14*Ref!$B$3+$I14*Ref!$B$4+$J14 -> 45.5 | L14: =K14-F14 -> -0.5 | M14: =IF(K14>0,100*L14/K14,0) -> -1.0989011
... A37: =IF(B37="","",MAX(A$2:A36)+1) -> 35 | B37: Χοιρινό κοντοσούβλι (εκτίμηση) | C37: Κρέας | D37: gr | E37: 100 | F37: 250 | G37: 28 | H37: 0 | I37: 15 | K37: =$G37*Ref!$B$2+$H37*Ref!$B$3+$I37*Ref!$B$4+$J37 -> 247 | L37: =K37-F37 -> -3 | M37: =IF(K37>0,100*L37/K37,0) -> -1.2145749
A38: =IF(B38="","",MAX(A$2:A37)+1) -> 36 | B38: Μπύρα 6% | C38: Ποτά | D38: gr | E38: 100 | F38: 43 | G38: 0.5 | H38: 3.6 | I38: 0 | J38: 43 | K38: =$G38*Ref!$B$2+$H38*Ref!$B$3+$I38*Ref!$B$4+$J38 -> 59.4 | L38: =K38-F38 -> 16.4 | M38: =IF(K38>0,100*L38/K38,0) -> 27.609428
A39: =IF(B39="","",MAX(A$2:A38)+1) -> 37 | B39: Κρασί 10% | C39: Ποτά | D39: gr | E39: 100 | F39: 85 | J39: 85 | K39: =$G39*Ref!$B$2+$H39*Ref!$B$3+$I39*Ref!$B$4+$J39 -> 85 | L39: =K39-F39 -> 0 | M39: =IF(K39>0,100*L39/K39,0) -> 0
A40: =IF(B40="","",MAX(A$2:A39)+1) -> 38 | B40: Κρασί 15% | C40: Ποτά | D40: gr | E40: 100 | F40: 137 | J40: 137 | K40: =$G40*Ref!$B$2+$H40*Ref!$B$3+$I40*Ref!$B$4+$J40 -> 137 | L40: =K40-F40 -> 0 | M40: =IF(K40>0,100*L40/K40,0) -> 0
A41: =IF(B41="","",MAX(A$2:A40)+1) -> 39 | B41: Ποτό 40% | C41: Ποτά | D41: gr | E41: 100 | F41: 280 | J41: 280 | K41: =$G41*Ref!$B$2+$H41*Ref!$B$3+$I41*Ref!$B$4+$J41 -> 280 | L41: =K41-F41 -> 0 | M41: =IF(K41>0,100*L41/K41,0) -> 0
A42: =IF(B42="","",MAX(A$2:A41)+1) -> 40 | B42: Πίτσα Τζάιαντ Χαμόν Μανιτάρια | C42: Γουρουνιές | D42: pc | E42: 1 | F42: 200 | G42: 10 | H42: 25 | I42: 7 | K42: =$G42*Ref!$B$2+$H42*Ref!$B$3+$I42*Ref!$B$4+$J42 -> 203 | L42: =K42-F42 -> 3 | M42: =IF(K42>0,100*L42/K42,0) -> 1.4778325
A43: =IF(B43="","",MAX(A$2:A42)+1) -> 41 | B43: Κολοκύθια | C43: Ζαρζαβατικά | D43: gr | E43: 100 | F43: 19 | G43: 1.2 | H43: 3.1 | I43: 0.3 | K43: =$G43*Ref!$B$2+$H43*Ref!$B$3+$I43*Ref!$B$4+$J43 -> 19.9 | L43: =K43-F43 -> 0.9 | M43: =IF(K43>0,100*L43/K43,0) -> 4.5226131
A44: =IF(B44="","",MAX(A$2:A43)+1) -> 42 | B44: Τυρί Κρέμα Φρέσκο ΑΒ Light | C44: Γαλακτοκομικά | D44: gr | E44: 100 | F44: 190 | G44: 7.8 | H44: 3.3 | I44: 16 | K44: =$G44*Ref!$B$2+$H44*Ref!$B$3+$I44*Ref!$B$4+$J44 -> 188.4 | L44: =K44-F44 -> -1.6 | M44: =IF(K44>0,100*L44/K44,0) -> -0.8492569
A45: =IF(B45="","",MAX(A$2:A44)+1) -> 43 | B45: Μέλι | C45: Γλυκά | D45: gr | E45: 100 | F45: 304 | G45: 0.3 | H45: 82.6 | K45: =$G45*Ref!$B$2+$H45*Ref!$B$3+$I45*Ref!$B$4+$J45 -> 331.6 | L45: =K45-F45 -> 27.6 | M45: =IF(K45>0,100*L45/K45,0) -> 8.3232811
A46: =IF(B46="","",MAX(A$2:A45)+1) -> 44 | B46: Τόνικ Tuborg | C46: Ποτά | D46: gr | E46: 100 | F46: 33 | G46: 0 | H46: 7.9 | I46: 0 | K46: =$G46*Ref!$B$2+$H46*Ref!$B$3+$I46*Ref!$B$4+$J46 -> 31.6 | L46: =K46-F46 -> -1.4 | M46: =IF(K46>0,100*L46/K46,0) -> -4.4303797
A47: =IF(B47="","",MAX(A$2:A46)+1) -> 45 | B47: Καρότα | C47: Ζαρζαβατικά | D47: gr | E47: 100 | F47: 42 | G47: 1.1 | H47: 9.7 | I47: 0.2 | K47: =$G47*Ref!$B$2+$H47*Ref!$B$3+$I47*Ref!$B$4+$J47 -> 45 | L47: =K47-F47 -> 3 | M47: =IF(K47>0,100*L47/K47,0) -> 6.6666667
A48: =IF(B48="","",MAX(A$2:A47)+1) -> 46 | B48: Γαλοπούλα Στήθος | C48: Πουλερικά | D48: gr | E48: 100 | F48: 111 | G48: 25 | H48: 0 | I48: 1 | K48: =$G48*Ref!$B$2+$H48*Ref!$B$3+$I48*Ref!$B$4+$J48 -> 109 | L48: =K48-F48 -> -2 | M48: =IF(K48>0,100*L48/K48,0) -> -1.8348624
A49: =IF(B49="","",MAX(A$2:A48)+1) -> 47 | B49: Φρυγανιά Τριμμένη ΑΒ | C49: Άλευρα | D49: gr | E49: 100 | F49: 408 | G49: 14.5 | H49: 69.1 | I49: 7.5 | K49: =$G49*Ref!$B$2+$H49*Ref!$B$3+$I49*Ref!$B$4+$J49 -> 401.9 | L49: =K49-F49 -> -6.1 | M49: =IF(K49>0,100*L49/K49,0) -> -1.5177905
A50: =IF(B50="","",MAX(A$2:A49)+1) -> 48 | B50: Ψάρι ψητό | C50: Ψαρικά | D50: gr | E50: 100 | F50: 164 | G50: 23 | H50: 0 | I50: 8 | K50: =$G50*Ref!$B$2+$H50*Ref!$B$3+$I50*Ref!$B$4+$J50 -> 164 | L50: =K50-F50 -> 0 | M50: =IF(K50>0,100*L50/K50,0) -> 0
A51: =IF(B51="","",MAX(A$2:A50)+1) -> 49 | B51: Καλαμάρι ψητό | C51: Ψαρικά | D51: gr | E51: 100 | F51: 167 | G51: 18 | H51: 8 | I51: 7 | K51: =$G51*Ref!$B$2+$H51*Ref!$B$3+$I51*Ref!$B$4+$J51 -> 167 | L51: =K51-F51 -> 0 | M51: =IF(K51>0,100*L51/K51,0) -> 0
A52: =IF(B52="","",MAX(A$2:A51)+1) -> 50 | B52: Πατάτα | C52: Ζαρζαβατικά | D52: gr | E52: 100 | F52: 76 | G52: 2 | H52: 17 | I52: 0 | K52: =$G52*Ref!$B$2+$H52*Ref!$B$3+$I52*Ref!$B$4+$J52 -> 76 | L52: =K52-F52 -> 0 | M52: =IF(K52>0,100*L52/K52,0) -> 0
A53: =IF(B53="","",MAX(A$2:A52)+1) -> 51 | B53: Χοιρινό | C53: Κρέας | D53: gr | E53: 100 | G53: 27 | H53: 0 | I53: 14 | K53: =$G53*Ref!$B$2+$H53*Ref!$B$3+$I53*Ref!$B$4+$J53 -> 234 | L53: =K53-F53 -> 234 | M53: =IF(K53>0,100*L53/K53,0) -> 100
A54: =IF(B54="","",MAX(A$2:A53)+1) -> 52 | B54: Σοκολάτα Υγείας Παυλίδη | C54: Γλυκά | D54: gr | E54: 100 | F54: 525 | G54: 4.4 | H54: 54.5 | I54: 30.5 | K54: =$G54*Ref!$B$2+$H54*Ref!$B$3+$I54*Ref!$B$4+$J54 -> 510.1 | L54: =K54-F54 -> -14.9 | M54: =IF(K54>0,100*L54/K54,0) -> -2.9209959
A55: =IF(B55="","",MAX(A$2:A54)+1) -> 53 | B55: Μανιτάρια | C55: Ζαρζαβατικά | D55: gr | E55: 100 | F55: 22 | G55: 3.1 | H55: 3.3 | I55: 0.3 | K55: =$G55*Ref!$B$2+$H55*Ref!$B$3+$I55*Ref!$B$4+$J55 -> 28.3 | L55: =K55-F55 -> 6.3 | M55: =IF(K55>0,100*L55/K55,0) -> 22.261484
A56: =IF(B56="","",MAX(A$2:A55)+1) -> 54 | B56: Μπρόκολο | C56: Ζαρζαβατικά | D56: gr | E56: 100 | F56: 33 | G56: 2.8 | H56: 7 | I56: 0 | K56: =$G56*Ref!$B$2+$H56*Ref!$B$3+$I56*Ref!$B$4+$J56 -> 39.2 | L56: =K56-F56 -> 6.2 | M56: =IF(K56>0,100*L56/K56,0) -> 15.816327
A57: =IF(B57="","",MAX(A$2:A56)+1) -> 55 | B57: Αρακάς Κατεψυγμένος | C57: Κατεψυγμένα | D57: gr | E57: 100 | F57: 77 | G57: 5.2 | H57: 14 | I57: 0.4 | K57: =$G57*Ref!$B$2+$H57*Ref!$B$3+$I57*Ref!$B$4+$J57 -> 80.4 | L57: =K57-F57 -> 3.4 | M57: =IF(K57>0,100*L57/K57,0) -> 4.2288557
A58: =IF(B58="","",MAX(A$2:A57)+1) -> 56 | B58: Πελτές Ντομάτας | C58: Κονσέρβες | D58: gr | E58: 100 | F58: 85 | G58: 4.2 | H58: 16.1 | I58: 0.2 | K58: =$G58*Ref!$B$2+$H58*Ref!$B$3+$I58*Ref!$B$4+$J58 -> 83 | L58: =K58-F58 -> -2 | M58: =IF(K58>0,100*L58/K58,0) -> -2.4096386
A59: =IF(B59="","",MAX(A$2:A58)+1) -> 57 | B59: Γάλα Εβαπορέ ΝΟΥΝΟΥ Light | C59: Γαλακτοκομικά | D59: gr | E59: 100 | F59: 59 | G59: 3.7 | H59: 6 | I59: 2.2 | K59: =$G59*Ref!$B$2+$H59*Ref!$B$3+$I59*Ref!$B$4+$J59 -> 58.6 | L59: =K59-F59 -> -0.4 | M59: =IF(K59>0,100*L59/K59,0) -> -0.68259386
A60: =IF(B60="","",MAX(A$2:A59)+1) -> 58 | B60: Βούτυρο LURPAK | C60: Λίπη | D60: gr | E60: 100 | F60: 747 | G60: 0.6 | H60: 0.7 | I60: 82 | K60: =$G60*Ref!$B$2+$H60*Ref!$B$3+$I60*Ref!$B$4+$J60 -> 743.2 | L60: =K60-F60 -> -3.8 | M60: =IF(K60>0,100*L60/K60,0) -> -0.51130248
A61: =IF(B61="","",MAX(A$2:A60)+1) -> 59 | B61: Λάχανο | C61: Ζαρζαβατικά | D61: gr | E61: 100 | F61: 26 | G61: 1.3 | H61: 6 | I61: 0 | K61: =$G61*Ref!$B$2+$H61*Ref!$B$3+$I61*Ref!$B$4+$J61 -> 29.2 | L61: =K61-F61 -> 3.2 | M61: =IF(K61>0,100*L61/K61,0) -> 10.958904
A62: =IF(B62="","",MAX(A$2:A61)+1) -> 60 | B62: Μήλο | C62: Φρούτα | D62: gr | E62: 100 | F62: 52 | G62: 0.3 | H62: 14 | I62: 0.2 | K62: =$G62*Ref!$B$2+$H62*Ref!$B$3+$I62*Ref!$B$4+$J62 -> 59 | L62: =K62-F62 -> 7 | M62: =IF(K62>0,100*L62/K62,0) -> 11.864407
A63: =IF(B63="","",MAX(A$2:A62)+1) -> 61 | B63: Μαντερίνι | C63: Φρούτα | D63: gr | E63: 100 | F63: 50 | G63: 0.8 | H63: 13 | I63: 0.3 | K63: =$G63*Ref!$B$2+$H63*Ref!$B$3+$I63*Ref!$B$4+$J63 -> 57.9 | L63: =K63-F63 -> 7.9 | M63: =IF(K63>0,100*L63/K63,0) -> 13.644214
...

Sheet Συνδυασμοί
A1: id | B1: Όνομα | C1: Υλικά | D1: Μονάδα | E1: Ποσότητα | F1: Πρωτεΐνες g | G1: Υδατάνθρακες g | H1: Λίπη g | I1: Kcal Prote | J1: Kcal Carb | K1: Kcal Fat | L1: Θερμίδες
A2: =IF($B2<>"",IF($B2<>$B1,1,$A1+1),"") -> 1 | B2: Μελιτζανοπίλαφο | C2: Μελιτζάνες | D2: =IF(C2<>"",INDEX(Υλικά!$D$3:$D$130,MATCH(C2,Υλικά!$B$3:$B$130,0),1),"") -> gr | E2: 1380 | F2: =IF(C2<>"",$E2*INDEX(Υλικά!$G$3:$G$130,MATCH($C2,Υλικά!$B$3:$B$130,0),1)/INDEX(Υλικά!$E$3:$E$130,MATCH($C2,Υλικά!$B$3:$B$130,0),1),0) -> 13.8 | G2: =IF(C2<>"",$E2*INDEX(Υλικά!$H$3:$H$130,MATCH($C2,Υλικά!$B$3:$B$130,0),1)/INDEX(Υλικά!$E$3:$E$130,MATCH($C2,Υλικά!$B$3:$B$130,0),1),0) -> 81.42 | H2: =IF(C2<>"",$E2*INDEX(Υλικά!$I$3:$I$130,MATCH($C2,Υλικά!$B$3:$B$130,0),1)/INDEX(Υλικά!$E$3:$E$130,MATCH($C2,Υλικά!$B$3:$B$130,0),1),0) -> 2.76 | I2: =$F2*Ref!$B$2 -> 55.2 | J2: =$G2*Ref!$B$3 -> 325.68 | K2: =$H2*Ref!$B$4 -> 24.84 | L2: =SUM(I2:K2) -> 405.72
A3: =IF($B3<>"",IF($B3<>$B2,1,$A2+1),"") -> 2 | B3: Μελιτζανοπίλαφο | C3: Κρεμμύδι | D3: =IF(C3<>"",INDEX(Υλικά!$D$3:$D$130,MATCH(C3,Υλικά!$B$3:$B$130,0),1),"") -> gr | E3: 270 | F3: =IF(C3<>"",$E3*INDEX(Υλικά!$G$3:$G$130,MATCH($C3,Υλικά!$B$3:$B$130,0),1)/INDEX(Υλικά!$E$3:$E$130,MATCH($C3,Υλικά!$B$3:$B$130,0),1),0) -> 2.97 | G3: =IF(C3<>"",$E3*INDEX(Υλικά!$H$3:$H$130,MATCH($C3,Υλικά!$B$3:$B$130,0),1)/INDEX(Υλικά!$E$3:$E$130,MATCH($C3,Υλικά!$B$3:$B$130,0),1),0) -> 25.11 | H3: =IF(C3<>"",$E3*INDEX(Υλικά!$I$3:$I$130,MATCH($C3,Υλικά!$B$3:$B$130,0),1)/INDEX(Υλικά!$E$3:$E$130,MATCH($C3,Υλικά!$B$3:$B$130,0),1),0) -> 0.27 | I3: =$F3*Ref!$B$2 -> 11.88 | J3: =$G3*Ref!$B$3 -> 100.44 | K3: =$H3*Ref!$B$4 -> 2.43 | L3: =SUM(I3:K3) -> 114.75
A4: =IF($B4<>"",IF($B4<>$B3,1,$A3+1),"") -> 3 | B4: Μελιτζανοπίλαφο | C4: Πιπεριές | D4: =IF(C4<>"",INDEX(Υλικά!$D$3:$D$130,MATCH(C4,Υλικά!$B$3:$B$130,0),1),"") -> gr | E4: 120 | F4: =IF(C4<>"",$E4*INDEX(Υλικά!$G$3:$G$130,MATCH($C4,Υλικά!$B$3:$B$130,0),1)/INDEX(Υλικά!$E$3:$E$130,MATCH($C4,Υλικά!$B$3:$B$130,0),1),0) -> 1.08 | G4: =IF(C4<>"",$E4*INDEX(Υλικά!$H$3:$H$130,MATCH($C4,Υλικά!$B$3:$B$130,0),1)/INDEX(Υλικά!$E$3:$E$130,MATCH($C4,Υλικά!$B$3:$B$130,0),1),0) -> 5.52 | H4: =IF(C4<>"",$E4*INDEX(Υλικά!$I$3:$I$130,MATCH($C4,Υλικά!$B$3:$B$130,0),1)/INDEX(Υλικά!$E$3:$E$130,MATCH($C4,Υλικά!$B$3:$B$130,0),1),0) -> 0.24 | I4: =$F4*Ref!$B$2 -> 4.32 | J4: =$G4*Ref!$B$3 -> 22.08 | K4: =$H4*Ref!$B$4 -> 2.16 | L4: =SUM(I4:K4) -> 28.56
A5: =IF($B5<>"",IF($B5<>$B4,1,$A4+1),"") -> 4 | B5: Μελιτζανοπίλαφο | C5: Ζάχαρη | D5: =IF(C5<>"",INDEX(Υλικά!$D$3:$D$130,MATCH(C5,Υλικά!$B$3:$B$130,0),1),"") -> gr | E5: 5 | F5: =IF(C5<>"",$E5*INDEX(Υλικά!$G$3:$G$130,MATCH($C5,Υλικά!$B$3:$B$130,0),1)/INDEX(Υλικά!$E$3:$E$130,MATCH($C5,Υλικά!$B$3:$B$130,0),1),0) -> 0 | G5: =IF(C5<>"",$E5*INDEX(Υλικά!$H$3:$H$130,MATCH($C5,Υλικά!$B$3:$B$130,0),1)/INDEX(Υλικά!$E$3:$E$130,MATCH($C5,Υλικά!$B$3:$B$130,0),1),0) -> 5 | H5: =IF(C5<>"",$E5*INDEX(Υλικά!$I$3:$I$130,MATCH($C5,Υλικά!$B$3:$B$130,0),1)/INDEX(Υλικά!$E$3:$E$130,MATCH($C5,Υλικά!$B$3:$B$130,0),1),0) -> 0 | I5: =$F5*Ref!$B$2 -> 0 | J5: =$G5*Ref!$B$3 -> 20 | K5: =$H5*Ref!$B$4 -> 0 | L5: =SUM(I5:K5) -> 20
A6: =IF($B6<>"",IF($B6<>$B5,1,$A5+1),"") -> 5 | B6: Μελιτζανοπίλαφο | C6: Ελαιόλαδο | D6: =IF(C6<>"",INDEX(Υλικά!$D$3:$D$130,MATCH(C6,Υλικά!$B$3:$B$130,0),1),"") -> gr | E6: 50 | F6: =IF(C6<>"",$E6*INDEX(Υλικά!$G$3:$G$130,MATCH($C6,Υλικά!$B$3:$B$130,0),1)/INDEX(Υλικά!$E$3:$E$130,MATCH($C6,Υλικά!$B$3:$B$130,0),1),0) -> 0 | G6: =IF(C6<>"",$E6*INDEX(Υλικά!$H$3:$H$130,MATCH($C6,Υλικά!$B$3:$B$130,0),1)/INDEX(Υλικά!$E$3:$E$130,MATCH($C6,Υλικά!$B$3:$B$130,0),1),0) -> 0 | H6: =IF(C6<>"",$E6*INDEX(Υλικά!$I$3:$I$130,MATCH($C6,Υλικά!$B$3:$B$130,0),1)/INDEX(Υλικά!$E$3:$E$130,MATCH($C6,Υλικά!$B$3:$B$130,0),1),0) -> 46.65 | I6: =$F6*Ref!$B$2 -> 0 | J6: =$G6*Ref!$B$3 -> 0 | K6: =$H6*Ref!$B$4 -> 419.85 | L6: =SUM(I6:K6) -> 419.85
A7: =IF($B7<>"",IF($B7<>$B6,1,$A6+1),"") -> 6 | B7: Μελιτζανοπίλαφο | C7: Ντομάτα κονκασέ | D7: =IF(C7<>"",INDEX(Υλικά!$D$3:$D$130,MATCH(C7,Υλικά!$B$3:$B$130,0),1),"") -> pc | E7: 1 | F7: =IF(C7<>"",$E7*INDEX(Υλικά!$G$3:$G$130,MATCH($C7,Υλικά!$B$3:$B$130,0),1)/INDEX(Υλικά!$E$3:$E$130,MATCH($C7,Υλικά!$B$3:$B$130,0),1),0) -> 4.8 | G7: =IF(C7<>"",$E7*INDEX(Υλικά!$H$3:$H$130,MATCH($C7,Υλικά!$B$3:$B$130,0),1)/INDEX(Υλικά!$E$3:$E$130,MATCH($C7,Υλικά!$B$3:$B$130,0),1),0) -> 18.4 | H7: =IF(C7<>"",$E7*INDEX(Υλικά!$I$3:$I$130,MATCH($C7,Υλικά!$B$3:$B$130,0),1)/INDEX(Υλικά!$E$3:$E$130,MATCH($C7,Υλικά!$B$3:$B$130,0),1),0) -> 0.12 | I7: =$F7*Ref!$B$2 -> 19.2 | J7: =$G7*Ref!$B$3 -> 73.6 | K7: =$H7*Ref!$B$4 -> 1.08 | L7: =SUM(I7:K7) -> 93.88
A8: =IF($B8<>"",IF($B8<>$B7,1,$A7+1),"") -> 7 | B8: Μελιτζανοπίλαφο | C8: Ρύζι parboiled | D8: =IF(C8<>"",INDEX(Υλικά!$D$3:$D$130,MATCH(C8,Υλικά!$B$3:$B$130,0),1),"") -> gr | E8: 150 | F8: =IF(C8<>"",$E8*INDEX(Υλικά!$G$3:$G$130,MATCH($C8,Υλικά!$B$3:$B$130,0),1)/INDEX(Υλικά!$E$3:$E$130,MATCH($C8,Υλικά!$B$3:$B$130,0),1),0) -> 10.65 | G8: =IF(C8<>"",$E8*INDEX(Υλικά!$H$3:$H$130,MATCH($C8,Υλικά!$B$3:$B$130,0),1)/INDEX(Υλικά!$E$3:$E$130,MATCH($C8,Υλικά!$B$3:$B$130,0),1),0) -> 120 | H8: =IF(C8<>"",$E8*INDEX(Υλικά!$I$3:$I$130,MATCH($C8,Υλικά!$B$3:$B$130,0),1)/INDEX(Υλικά!$E$3:$E$130,MATCH($C8,Υλικά!$B$3:$B$130,0),1),0) -> 1.05 | I8: =$F8*Ref!$B$2 -> 42.6 | J8: =$G8*Ref!$B$3 -> 480 | K8: =$H8*Ref!$B$4 -> 9.45 | L8: =SUM(I8:K8) -> 532.05
A9: =IF($B9<>"",IF($B9<>$B8,1,$A8+1),"") -> 1 | B9: Χωριάτικη Σαλάτα | C9: Ντομάτα | D9: =IF(C9<>"",INDEX(Υλικά!$D$3:$D$130,MATCH(C9,Υλικά!$B$3:$B$130,0),1),"") -> gr | E9: 310 | F9: =IF(C9<>"",$E9*INDEX(Υλικά!$G$3:$G$130,MATCH($C9,Υλικά!$B$3:$B$130,0),1)/INDEX(Υλικά!$E$3:$E$130,MATCH($C9,Υλικά!$B$3:$B$130,0),1),0) -> 2.79 | G9: =IF(C9<>"",$E9*INDEX(Υλικά!$H$3:$H$130,MATCH($C9,Υλικά!$B$3:$B$130,0),1)/INDEX(Υλικά!$E$3:$E$130,MATCH($C9,Υλικά!$B$3:$B$130,0),1),0) -> 12.09 | H9: =IF(C9<>"",$E9*INDEX(Υλικά!$I$3:$I$130,MATCH($C9,Υλικά!$B$3:$B$130,0),1)/INDEX(Υλικά!$E$3:$E$130,MATCH($C9,Υλικά!$B$3:$B$130,0),1),0) -> 0.62 | I9: =$F9*Ref!$B$2 -> 11.16 | J9: =$G9*Ref!$B$3 -> 48.36 | K9: =$H9*Ref!$B$4 -> 5.58 | L9: =SUM(I9:K9) -> 65.1
A10: =IF($B10<>"",IF($B10<>$B9,1,$A9+1),"") -> 2 | B10: Χωριάτικη Σαλάτα | C10: Αγγούρι | D10: =IF(C10<>"",INDEX(Υλικά!$D$3:$D$130,MATCH(C10,Υλικά!$B$3:$B$130,0),1),"") -> gr | E10: 200 | F10: =IF(C10<>"",$E10*INDEX(Υλικά!$G$3:$G$130,MATCH($C10,Υλικά!$B$3:$B$130,0),1)/INDEX(Υλικά!$E$3:$E$130,MATCH($C10,Υλικά!$B$3:$B$130,0),1),0) -> 1.4 | G10: =IF(C10<>"",$E10*INDEX(Υλικά!$H$3:$H$130,MATCH($C10,Υλικά!$B$3:$B$130,0),1)/INDEX(Υλικά!$E$3:$E$130,MATCH($C10,Υλικά!$B$3:$B$130,0),1),0) -> 7.2 | H10: =IF(C10<>"",$E10*INDEX(Υλικά!$I$3:$I$130,MATCH($C10,Υλικά!$B$3:$B$130,0),1)/INDEX(Υλικά!$E$3:$E$130,MATCH($C10,Υλικά!$B$3:$B$130,0),1),0) -> 0.2 | I10: =$F10*Ref!$B$2 -> 5.6 | J10: =$G10*Ref!$B$3 -> 28.8 | K10: =$H10*Ref!$B$4 -> 1.8 | L10: =SUM(I10:K10) -> 36.2
A11: =IF($B11<>"",IF($B11<>$B10,1,$A10+1),"") -> 3 | B11: Χωριάτικη Σαλάτα | C11: Φέτα | D11: =IF(C11<>"",INDEX(Υλικά!$D$3:$D$130,MATCH(C11,Υλικά!$B$3:$B$130,0),1),"") -> gr | E11: 60 | F11: =IF(C11<>"",$E11*INDEX(Υλικά!$G$3:$G$130,MATCH($C11,Υλικά!$B$3:$B$130,0),1)/INDEX(Υλικά!$E$3:$E$130,MATCH($C11,Υλικά!$B$3:$B$130,0),1),0) -> 8.52 | G11: =IF(C11<>"",$E11*INDEX(Υλικά!$H$3:$H$130,MATCH($C11,Υλικά!$B$3:$B$130,0),1)/INDEX(Υλικά!$E$3:$E$130,MATCH($C11,Υλικά!$B$3:$B$130,0),1),0) -> 2.46 | H11: =IF(C11<>"",$E11*INDEX(Υλικά!$I$3:$I$130,MATCH($C11,Υλικά!$B$3:$B$130,0),1)/INDEX(Υλικά!$E$3:$E$130,MATCH($C11,Υλικά!$B$3:$B$130,0),1),0) -> 12.78 | I11: =$F11*Ref!$B$2 -> 34.08 | J11: =$G11*Ref!$B$3 -> 9.84 | K11: =$H11*Ref!$B$4 -> 115.02 | L11: =SUM(I11:K11) -> 158.94
A12: =IF($B12<>"",IF($B12<>$B11,1,$A11+1),"") -> 4 | B12: Χωριάτικη Σαλάτα | C12: Ελιές | D12: =IF(C12<>"",INDEX(Υλικά!$D$3:$D$130,MATCH(C12,Υλικά!$B$3:$B$130,0),1),"") -> pc | E12: 10 | F12: =IF(C12<>"",$E12*INDEX(Υλικά!$G$3:$G$130,MATCH($C12,Υλικά!$B$3:$B$130,0),1)/INDEX(Υλικά!$E$3:$E$130,MATCH($C12,Υλικά!$B$3:$B$130,0),1),0) -> 0.4 | G12: =IF(C12<>"",$E12*INDEX(Υλικά!$H$3:$H$130,MATCH($C12,Υλικά!$B$3:$B$130,0),1)/INDEX(Υλικά!$E$3:$E$130,MATCH($C12,Υλικά!$B$3:$B$130,0),1),0) -> 2.8 | H12: =IF(C12<>"",$E12*INDEX(Υλικά!$I$3:$I$130,MATCH($C12,Υλικά!$B$3:$B$130,0),1)/INDEX(Υλικά!$E$3:$E$130,MATCH($C12,Υλικά!$B$3:$B$130,0),1),0) -> 4.7 | I12: =$F12*Ref!$B$2 -> 1.6 | J12: =$G12*Ref!$B$3 -> 11.2 | K12: =$H12*Ref!$B$4 -> 42.3 | L12: =SUM(I12:K12) -> 55.1
A13: =IF($B13<>"",IF($B13<>$B12,1,$A12+1),"") -> 5 | B13: Χωριάτικη Σαλάτα | C13: Ελαιόλαδο | D13: =IF(C13<>"",INDEX(Υλικά!$D$3:$D$130,MATCH(C13,Υλικά!$B$3:$B$130,0),1),"") -> gr | E13: 10 | F13: =IF(C13<>"",$E13*INDEX(Υλικά!$G$3:$G$130,MATCH($C13,Υλικά!$B$3:$B$130,0),1)/INDEX(Υλικά!$E$3:$E$130,MATCH($C13,Υλικά!$B$3:$B$130,0),1),0) -> 0 | G13: =IF(C13<>"",$E13*INDEX(Υλικά!$H$3:$H$130,MATCH($C13,Υλικά!$B$3:$B$130,0),1)/INDEX(Υλικά!$E$3:$E$130,MATCH($C13,Υλικά!$B$3:$B$130,0),1),0) -> 0 | H13: =IF(C13<>"",$E13*INDEX(Υλικά!$I$3:$I$130,MATCH($C13,Υλικά!$B$3:$B$130,0),1)/INDEX(Υλικά!$E$3:$E$130,MATCH($C13,Υλικά!$B$3:$B$130,0),1),0) -> 9.33 | I13: =$F13*Ref!$B$2 -> 0 | J13: =$G13*Ref!$B$3 -> 0 | K13: =$H13*Ref!$B$4 -> 83.97 | L13: =SUM(I13:K13) -> 83.97
... A54: =IF($B54<>"",IF($B54<>$B53,1,$A53+1),"") -> 5 | B54: Μπιφτέκια Γαλοπούλας | C54: Καρότα | D54: =IF(C54<>"",INDEX(Υλικά!$D$3:$D$130,MATCH(C54,Υλικά!$B$3:$B$130,0),1),"") -> gr | E54: 250 | F54: =IF(C54<>"",$E54*INDEX(Υλικά!$G$3:$G$130,MATCH($C54,Υλικά!$B$3:$B$130,0),1)/INDEX(Υλικά!$E$3:$E$130,MATCH($C54,Υλικά!$B$3:$B$130,0),1),0) -> 2.75 | G54: =IF(C54<>"",$E54*INDEX(Υλικά!$H$3:$H$130,MATCH($C54,Υλικά!$B$3:$B$130,0),1)/INDEX(Υλικά!$E$3:$E$130,MATCH($C54,Υλικά!$B$3:$B$130,0),1),0) -> 24.25 | H54: =IF(C54<>"",$E54*INDEX(Υλικά!$I$3:$I$130,MATCH($C54,Υλικά!$B$3:$B$130,0),1)/INDEX(Υλικά!$E$3:$E$130,MATCH($C54,Υλικά!$B$3:$B$130,0),1),0) -> 0.5 | I54: =$F54*Ref!$B$2 -> 11 | J54: =$G54*Ref!$B$3 -> 97 | K54: =$H54*Ref!$B$4 -> 4.5 | L54: =SUM(I54:K54) -> 112.5
A55: =IF($B55<>"",IF($B55<>$B54,1,$A54+1),"") -> 6 | B55: Μπιφτέκια Γαλοπούλας | C55: Φρυγανιά Τριμμένη ΑΒ | D55: =IF(C55<>"",INDEX(Υλικά!$D$3:$D$130,MATCH(C55,Υλικά!$B$3:$B$130,0),1),"") -> gr | E55: 100 | F55: =IF(C55<>"",$E55*INDEX(Υλικά!$G$3:$G$130,MATCH($C55,Υλικά!$B$3:$B$130,0),1)/INDEX(Υλικά!$E$3:$E$130,MATCH($C55,Υλικά!$B$3:$B$130,0),1),0) -> 14.5 | G55: =IF(C55<>"",$E55*INDEX(Υλικά!$H$3:$H$130,MATCH($C55,Υλικά!$B$3:$B$130,0),1)/INDEX(Υλικά!$E$3:$E$130,MATCH($C55,Υλικά!$B$3:$B$130,0),1),0) -> 69.1 | H55: =IF(C55<>"",$E55*INDEX(Υλικά!$I$3:$I$130,MATCH($C55,Υλικά!$B$3:$B$130,0),1)/INDEX(Υλικά!$E$3:$E$130,MATCH($C55,Υλικά!$B$3:$B$130,0),1),0) -> 7.5 | I55: =$F55*Ref!$B$2 -> 58 | J55: =$G55*Ref!$B$3 -> 276.4 | K55: =$H55*Ref!$B$4 -> 67.5 | L55: =SUM(I55:K55) -> 401.9 | R55: =150*3650/2000 -> 273.75
A56: =IF($B56<>"",IF($B56<>$B55,1,$A55+1),"") -> 7 | B56: Μπιφτέκια Γαλοπούλας | C56: Αυγά | D56: =IF(C56<>"",INDEX(Υλικά!$D$3:$D$130,MATCH(C56,Υλικά!$B$3:$B$130,0),1),"") -> pc | E56: 1 | F56: =IF(C56<>"",$E56*INDEX(Υλικά!$G$3:$G$130,MATCH($C56,Υλικά!$B$3:$B$130,0),1)/INDEX(Υλικά!$E$3:$E$130,MATCH($C56,Υλικά!$B$3:$B$130,0),1),0) -> 7.8 | G56: =IF(C56<>"",$E56*INDEX(Υλικά!$H$3:$H$130,MATCH($C56,Υλικά!$B$3:$B$130,0),1)/INDEX(Υλικά!$E$3:$E$130,MATCH($C56,Υλικά!$B$3:$B$130,0),1),0) -> 0.66 | H56: =IF(C56<>"",$E56*INDEX(Υλικά!$I$3:$I$130,MATCH($C56,Υλικά!$B$3:$B$130,0),1)/INDEX(Υλικά!$E$3:$E$130,MATCH($C56,Υλικά!$B$3:$B$130,0),1),0) -> 6.6 | I56: =$F56*Ref!$B$2 -> 31.2 | J56: =$G56*Ref!$B$3 -> 2.64 | K56: =$H56*Ref!$B$4 -> 59.4 | L56: =SUM(I56:K56) -> 93.24
A57: =IF($B57<>"",IF($B57<>$B56,1,$A56+1),"") -> 1 | B57: Σουτζουκάκια Σμυρνέικα | C57: Μοσχάρι άπαχο | D57: =IF(C57<>"",INDEX(Υλικά!$D$3:$D$130,MATCH(C57,Υλικά!$B$3:$B$130,0),1),"") -> gr | E57: 1050 | F57: =IF(C57<>"",$E57*INDEX(Υλικά!$G$3:$G$130,MATCH($C57,Υλικά!$B$3:$B$130,0),1)/INDEX(Υλικά!$E$3:$E$130,MATCH($C57,Υλικά!$B$3:$B$130,0),1),0) -> 252 | G57: =IF(C57<>"",$E57*INDEX(Υλικά!$H$3:$H$130,MATCH($C57,Υλικά!$B$3:$B$130,0),1)/INDEX(Υλικά!$E$3:$E$130,MATCH($C57,Υλικά!$B$3:$B$130,0),1),0) -> 0 | H57: =IF(C57<>"",$E57*INDEX(Υλικά!$I$3:$I$130,MATCH($C57,Υλικά!$B$3:$B$130,0),1)/INDEX(Υλικά!$E$3:$E$130,MATCH($C57,Υλικά!$B$3:$B$130,0),1),0) -> 84 | I57: =$F57*Ref!$B$2 -> 1008 | J57: =$G57*Ref!$B$3 -> 0 | K57: =$H57*Ref!$B$4 -> 756 | L57: =SUM(I57:K57) -> 1764
A58: =IF($B58<>"",IF($B58<>$B57,1,$A57+1),"") -> 2 | B58: Σουτζουκάκια Σμυρνέικα | C58: Χοιρινό | D58: =IF(C58<>"",INDEX(Υλικά!$D$3:$D$130,MATCH(C58,Υλικά!$B$3:$B$130,0),1),"") -> gr | E58: 525 | F58: =IF(C58<>"",$E58*INDEX(Υλικά!$G$3:$G$130,MATCH($C58,Υλικά!$B$3:$B$130,0),1)/INDEX(Υλικά!$E$3:$E$130,MATCH($C58,Υλικά!$B$3:$B$130,0),1),0) -> 141.75 | G58: =IF(C58<>"",$E58*INDEX(Υλικά!$H$3:$H$130,MATCH($C58,Υλικά!$B$3:$B$130,0),1)/INDEX(Υλικά!$E$3:$E$130,MATCH($C58,Υλικά!$B$3:$B$130,0),1),0) -> 0 | H58: =IF(C58<>"",$E58*INDEX(Υλικά!$I$3:$I$130,MATCH($C58,Υλικά!$B$3:$B$130,0),1)/INDEX(Υλικά!$E$3:$E$130,MATCH($C58,Υλικά!$B$3:$B$130,0),1),0) -> 73.5 | I58: =$F58*Ref!$B$2 -> 567 | J58: =$G58*Ref!$B$3 -> 0 | K58: =$H58*Ref!$B$4 -> 661.5 | L58: =SUM(I58:K58) -> 1228.5
A59: =IF($B59<>"",IF($B59<>$B58,1,$A58+1),"") -> 3 | B59: Σουτζουκάκια Σμυρνέικα | C59: Ελαιόλαδο | D59: =IF(C59<>"",INDEX(Υλικά!$D$3:$D$130,MATCH(C59,Υλικά!$B$3:$B$130,0),1),"") -> gr | E59: 30 | F59: =IF(C59<>"",$E59*INDEX(Υλικά!$G$3:$G$130,MATCH($C59,Υλικά!$B$3:$B$130,0),1)/INDEX(Υλικά!$E$3:$E$130,MATCH($C59,Υλικά!$B$3:$B$130,0),1),0) -> 0 | G59: =IF(C59<>"",$E59*INDEX(Υλικά!$H$3:$H$130,MATCH($C59,Υλικά!$B$3:$B$130,0),1)/INDEX(Υλικά!$E$3:$E$130,MATCH($C59,Υλικά!$B$3:$B$130,0),1),0) -> 0 | H59: =IF(C59<>"",$E59*INDEX(Υλικά!$I$3:$I$130,MATCH($C59,Υλικά!$B$3:$B$130,0),1)/INDEX(Υλικά!$E$3:$E$130,MATCH($C59,Υλικά!$B$3:$B$130,0),1),0) -> 27.99 | I59: =$F59*Ref!$B$2 -> 0 | J59: =$G59*Ref!$B$3 -> 0 | K59: =$H59*Ref!$B$4 -> 251.91 | L59: =SUM(I59:K59) -> 251.91
A60: =IF($B60<>"",IF($B60<>$B59,1,$A59+1),"") -> 4 | B60: Σουτζουκάκια Σμυρνέικα | C60: Φρυγανιά Τριμμένη ΑΒ | D60: =IF(C60<>"",INDEX(Υλικά!$D$3:$D$130,MATCH(C60,Υλικά!$B$3:$B$130,0),1),"") -> gr | E60: 100 | F60: =IF(C60<>"",$E60*INDEX(Υλικά!$G$3:$G$130,MATCH($C60,Υλικά!$B$3:$B$130,0),1)/INDEX(Υλικά!$E$3:$E$130,MATCH($C60,Υλικά!$B$3:$B$130,0),1),0) -> 14.5 | G60: =IF(C60<>"",$E60*INDEX(Υλικά!$H$3:$H$130,MATCH($C60,Υλικά!$B$3:$B$130,0),1)/INDEX(Υλικά!$E$3:$E$130,MATCH($C60,Υλικά!$B$3:$B$130,0),1),0) -> 69.1 | H60: =IF(C60<>"",$E60*INDEX(Υλικά!$I$3:$I$130,MATCH($C60,Υλικά!$B$3:$B$130,0),1)/INDEX(Υλικά!$E$3:$E$130,MATCH($C60,Υλικά!$B$3:$B$130,0),1),0) -> 7.5 | I60: =$F60*Ref!$B$2 -> 58 | J60: =$G60*Ref!$B$3 -> 276.4 | K60: =$H60*Ref!$B$4 -> 67.5 | L60: =SUM(I60:K60) -> 401.9
A61: =IF($B61<>"",IF($B61<>$B60,1,$A60+1),"") -> 5 | B61: Σουτζουκάκια Σμυρνέικα | C61: Ελαιόλαδο | D61: =IF(C61<>"",INDEX(Υλικά!$D$3:$D$130,MATCH(C61,Υλικά!$B$3:$B$130,0),1),"") -> gr | E61: 100 | F61: =IF(C61<>"",$E61*INDEX(Υλικά!$G$3:$G$130,MATCH($C61,Υλικά!$B$3:$B$130,0),1)/INDEX(Υλικά!$E$3:$E$130,MATCH($C61,Υλικά!$B$3:$B$130,0),1),0) -> 0 | G61: =IF(C61<>"",$E61*INDEX(Υλικά!$H$3:$H$130,MATCH($C61,Υλικά!$B$3:$B$130,0),1)/INDEX(Υλικά!$E$3:$E$130,MATCH($C61,Υλικά!$B$3:$B$130,0),1),0) -> 0 | H61: =IF(C61<>"",$E61*INDEX(Υλικά!$I$3:$I$130,MATCH($C61,Υλικά!$B$3:$B$130,0),1)/INDEX(Υλικά!$E$3:$E$130,MATCH($C61,Υλικά!$B$3:$B$130,0),1),0) -> 93.3 | I61: =$F61*Ref!$B$2 -> 0 | J61: =$G61*Ref!$B$3 -> 0 | K61: =$H61*Ref!$B$4 -> 839.7 | L61: =SUM(I61:K61) -> 839.7
A62: =IF($B62<>"",IF($B62<>$B61,1,$A61+1),"") -> 6 | B62: Σουτζουκάκια Σμυρνέικα | C62: Ντομάτα κονκασέ | D62: =IF(C62<>"",INDEX(Υλικά!$D$3:$D$130,MATCH(C62,Υλικά!$B$3:$B$130,0),1),"") -> pc | E62: 2 | F62: =IF(C62<>"",$E62*INDEX(Υλικά!$G$3:$G$130,MATCH($C62,Υλικά!$B$3:$B$130,0),1)/INDEX(Υλικά!$E$3:$E$130,MATCH($C62,Υλικά!$B$3:$B$130,0),1),0) -> 9.6 | G62: =IF(C62<>"",$E62*INDEX(Υλικά!$H$3:$H$130,MATCH($C62,Υλικά!$B$3:$B$130,0),1)/INDEX(Υλικά!$E$3:$E$130,MATCH($C62,Υλικά!$B$3:$B$130,0),1),0) -> 36.8 | H62: =IF(C62<>"",$E62*INDEX(Υλικά!$I$3:$I$130,MATCH($C62,Υλικά!$B$3:$B$130,0),1)/INDEX(Υλικά!$E$3:$E$130,MATCH($C62,Υλικά!$B$3:$B$130,0),1),0) -> 0.24 | I62: =$F62*Ref!$B$2 -> 38.4 | J62: =$G62*Ref!$B$3 -> 147.2 | K62: =$H62*Ref!$B$4 -> 2.16 | L62: =SUM(I62:K62) -> 187.76
A63: =IF($B63<>"",IF($B63<>$B62,1,$A62+1),"") -> 1 | B63: Κάρυ Λαχανικών Γαλοπούλα | C63: Ελαιόλαδο | D63: =IF(C63<>"",INDEX(Υλικά!$D$3:$D$130,MATCH(C63,Υλικά!$B$3:$B$130,0),1),"") -> gr | E63: 35 | F63: =IF(C63<>"",$E63*INDEX(Υλικά!$G$3:$G$130,MATCH($C63,Υλικά!$B$3:$B$130,0),1)/INDEX(Υλικά!$E$3:$E$130,MATCH($C63,Υλικά!$B$3:$B$130,0),1),0) -> 0 | G63: =IF(C63<>"",$E63*INDEX(Υλικά!$H$3:$H$130,MATCH($C63,Υλικά!$B$3:$B$130,0),1)/INDEX(Υλικά!$E$3:$E$130,MATCH($C63,Υλικά!$B$3:$B$130,0),1),0) -> 0 | H63: =IF(C63<>"",$E63*INDEX(Υλικά!$I$3:$I$130,MATCH($C63,Υλικά!$B$3:$B$130,0),1)/INDEX(Υλικά!$E$3:$E$130,MATCH($C63,Υλικά!$B$3:$B$130,0),1),0) -> 32.655 | I63: =$F63*Ref!$B$2 -> 0 | J63: =$G63*Ref!$B$3 -> 0 | K63: =$H63*Ref!$B$4 -> 293.895 | L63: =SUM(I63:K63) -> 293.895
A64: =IF($B64<>"",IF($B64<>$B63,1,$A63+1),"") -> 2 | B64: Κάρυ Λαχανικών Γαλοπούλα | C64: Κρεμμύδι | D64: =IF(C64<>"",INDEX(Υλικά!$D$3:$D$130,MATCH(C64,Υλικά!$B$3:$B$130,0),1),"") -> gr | E64: 270 | F64: =IF(C64<>"",$E64*INDEX(Υλικά!$G$3:$G$130,MATCH($C64,Υλικά!$B$3:$B$130,0),1)/INDEX(Υλικά!$E$3:$E$130,MATCH($C64,Υλικά!$B$3:$B$130,0),1),0) -> 2.97 | G64: =IF(C64<>"",$E64*INDEX(Υλικά!$H$3:$H$130,MATCH($C64,Υλικά!$B$3:$B$130,0),1)/INDEX(Υλικά!$E$3:$E$130,MATCH($C64,Υλικά!$B$3:$B$130,0),1),0) -> 25.11 | H64: =IF(C64<>"",$E64*INDEX(Υλικά!$I$3:$I$130,MATCH($C64,Υλικά!$B$3:$B$130,0),1)/INDEX(Υλικά!$E$3:$E$130,MATCH($C64,Υλικά!$B$3:$B$130,0),1),0) -> 0.27 | I64: =$F64*Ref!$B$2 -> 11.88 | J64: =$G64*Ref!$B$3 -> 100.44 | K64: =$H64*Ref!$B$4 -> 2.43 | L64: =SUM(I64:K64) -> 114.75
A65: =IF($B65<>"",IF($B65<>$B64,1,$A64+1),"") -> 3 | B65: Κάρυ Λαχανικών Γαλοπούλα | C65: Γαλοπούλα Στήθος | D65: =IF(C65<>"",INDEX(Υλικά!$D$3:$D$130,MATCH(C65,Υλικά!$B$3:$B$130,0),1),"") -> gr | E65: 540 | F65: =IF(C65<>"",$E65*INDEX(Υλικά!$G$3:$G$130,MATCH($C65,Υλικά!$B$3:$B$130,0),1)/INDEX(Υλικά!$E$3:$E$130,MATCH($C65,Υλικά!$B$3:$B$130,0),1),0) -> 135 | G65: =IF(C65<>"",$E65*INDEX(Υλικά!$H$3:$H$130,MATCH($C65,Υλικά!$B$3:$B$130,0),1)/INDEX(Υλικά!$E$3:$E$130,MATCH($C65,Υλικά!$B$3:$B$130,0),1),0) -> 0 | H65: =IF(C65<>"",$E65*INDEX(Υλικά!$I$3:$I$130,MATCH($C65,Υλικά!$B$3:$B$130,0),1)/INDEX(Υλικά!$E$3:$E$130,MATCH($C65,Υλικά!$B$3:$B$130,0),1),0) -> 5.4 | I65: =$F65*Ref!$B$2 -> 540 | J65: =$G65*Ref!$B$3 -> 0 | K65: =$H65*Ref!$B$4 -> 48.6 | L65: =SUM(I65:K65) -> 588.6
A66: =IF($B66<>"",IF($B66<>$B65,1,$A65+1),"") -> 4 | B66: Κάρυ Λαχανικών Γαλοπούλα | C66: Καρότα | D66: =IF(C66<>"",INDEX(Υλικά!$D$3:$D$130,MATCH(C66,Υλικά!$B$3:$B$130,0),1),"") -> gr | E66: 310 | F66: =IF(C66<>"",$E66*INDEX(Υλικά!$G$3:$G$130,MATCH($C66,Υλικά!$B$3:$B$130,0),1)/INDEX(Υλικά!$E$3:$E$130,MATCH($C66,Υλικά!$B$3:$B$130,0),1),0) -> 3.41 | G66: =IF(C66<>"",$E66*INDEX(Υλικά!$H$3:$H$130,MATCH($C66,Υλικά!$B$3:$B$130,0),1)/INDEX(Υλικά!$E$3:$E$130,MATCH($C66,Υλικά!$B$3:$B$130,0),1),0) -> 30.07 | H66: =IF(C66<>"",$E66*INDEX(Υλικά!$I$3:$I$130,MATCH($C66,Υλικά!$B$3:$B$130,0),1)/INDEX(Υλικά!$E$3:$E$130,MATCH($C66,Υλικά!$B$3:$B$130,0),1),0) -> 0.62 | I66: =$F66*Ref!$B$2 -> 13.64 | J66: =$G66*Ref!$B$3 -> 120.28 | K66: =$H66*Ref!$B$4 -> 5.58 | L66: =SUM(I66:K66) -> 139.5
A67: =IF($B67<>"",IF($B67<>$B66,1,$A66+1),"") -> 5 | B67: Κάρυ Λαχανικών Γαλοπούλα | C67: Πατάτα | D67: =IF(C67<>"",INDEX(Υλικά!$D$3:$D$130,MATCH(C67,Υλικά!$B$3:$B$130,0),1),"") -> gr | E67: 570 | F67: =IF(C67<>"",$E67*INDEX(Υλικά!$G$3:$G$130,MATCH($C67,Υλικά!$B$3:$B$130,0),1)/INDEX(Υλικά!$E$3:$E$130,MATCH($C67,Υλικά!$B$3:$B$130,0),1),0) -> 11.4 | G67: =IF(C67<>"",$E67*INDEX(Υλικά!$H$3:$H$130,MATCH($C67,Υλικά!$B$3:$B$130,0),1)/INDEX(Υλικά!$E$3:$E$130,MATCH($C67,Υλικά!$B$3:$B$130,0),1),0) -> 96.9 | H67: =IF(C67<>"",$E67*INDEX(Υλικά!$I$3:$I$130,MATCH($C67,Υλικά!$B$3:$B$130,0),1)/INDEX(Υλικά!$E$3:$E$130,MATCH($C67,Υλικά!$B$3:$B$130,0),1),0) -> 0 | I67: =$F67*Ref!$B$2 -> 45.6 | J67: =$G67*Ref!$B$3 -> 387.6 | K67: =$H67*Ref!$B$4 -> 0 | L67: =SUM(I67:K67) -> 433.2
... A79: =IF($B79<>"",IF($B79<>$B78,1,$A78+1),"") -> 2 | B79: Πουρές | C79: Γάλα Εβαπορέ ΝΟΥΝΟΥ Light | D79: =IF(C79<>"",INDEX(Υλικά!$D$3:$D$130,MATCH(C79,Υλικά!$B$3:$B$130,0),1),"") -> gr | E79: 250 | F79: =IF(C79<>"",$E79*INDEX(Υλικά!$G$3:$G$130,MATCH($C79,Υλικά!$B$3:$B$130,0),1)/INDEX(Υλικά!$E$3:$E$130,MATCH($C79,Υλικά!$B$3:$B$130,0),1),0) -> 9.25 | G79: =IF(C79<>"",$E79*INDEX(Υλικά!$H$3:$H$130,MATCH($C79,Υλικά!$B$3:$B$130,0),1)/INDEX(Υλικά!$E$3:$E$130,MATCH($C79,Υλικά!$B$3:$B$130,0),1),0) -> 15 | H79: =IF(C79<>"",$E79*INDEX(Υλικά!$I$3:$I$130,MATCH($C79,Υλικά!$B$3:$B$130,0),1)/INDEX(Υλικά!$E$3:$E$130,MATCH($C79,Υλικά!$B$3:$B$130,0),1),0) -> 5.5 | I79: =$F79*Ref!$B$2 -> 37 | J79: =$G79*Ref!$B$3 -> 60 | K79: =$H79*Ref!$B$4 -> 49.5 | L79: =SUM(I79:K79) -> 146.5
A80: =IF($B80<>"",IF($B80<>$B79,1,$A79+1),"") -> 3 | B80: Πουρές | C80: Βούτυρο LURPAK | D80: =IF(C80<>"",INDEX(Υλικά!$D$3:$D$130,MATCH(C80,Υλικά!$B$3:$B$130,0),1),"") -> gr | E80: 38 | F80: =IF(C80<>"",$E80*INDEX(Υλικά!$G$3:$G$130,MATCH($C80,Υλικά!$B$3:$B$130,0),1)/INDEX(Υλικά!$E$3:$E$130,MATCH($C80,Υλικά!$B$3:$B$130,0),1),0) -> 0.228 | G80: =IF(C80<>"",$E80*INDEX(Υλικά!$H$3:$H$130,MATCH($C80,Υλικά!$B$3:$B$130,0),1)/INDEX(Υλικά!$E$3:$E$130,MATCH($C80,Υλικά!$B$3:$B$130,0),1),0) -> 0.266 | H80: =IF(C80<>"",$E80*INDEX(Υλικά!$I$3:$I$130,MATCH($C80,Υλικά!$B$3:$B$130,0),1)/INDEX(Υλικά!$E$3:$E$130,MATCH($C80,Υλικά!$B$3:$B$130,0),1),0) -> 31.16 | I80: =$F80*Ref!$B$2 -> 0.912 | J80: =$G80*Ref!$B$3 -> 1.064 | K80: =$H80*Ref!$B$4 -> 280.44 | L80: =SUM(I80:K80) -> 282.416 | M80: =SUM(L78:L80) -> 1416.916
A81: =IF($B81<>"",IF($B81<>$B80,1,$A80+1),"") -> 1 | B81: Μοσχάρι με μαύρη μπύρα | C81: Μοσχάρι άπαχο | D81: =IF(C81<>"",INDEX(Υλικά!$D$3:$D$130,MATCH(C81,Υλικά!$B$3:$B$130,0),1),"") -> gr | E81: 1350 | F81: =IF(C81<>"",$E81*INDEX(Υλικά!$G$3:$G$130,MATCH($C81,Υλικά!$B$3:$B$130,0),1)/INDEX(Υλικά!$E$3:$E$130,MATCH($C81,Υλικά!$B$3:$B$130,0),1),0) -> 324 | G81: =IF(C81<>"",$E81*INDEX(Υλικά!$H$3:$H$130,MATCH($C81,Υλικά!$B$3:$B$130,0),1)/INDEX(Υλικά!$E$3:$E$130,MATCH($C81,Υλικά!$B$3:$B$130,0),1),0) -> 0 | H81: =IF(C81<>"",$E81*INDEX(Υλικά!$I$3:$I$130,MATCH($C81,Υλικά!$B$3:$B$130,0),1)/INDEX(Υλικά!$E$3:$E$130,MATCH($C81,Υλικά!$B$3:$B$130,0),1),0) -> 108 | I81: =$F81*Ref!$B$2 -> 1296 | J81: =$G81*Ref!$B$3 -> 0 | K81: =$H81*Ref!$B$4 -> 972 | L81: =SUM(I81:K81) -> 2268
A82: =IF($B82<>"",IF($B82<>$B81,1,$A81+1),"") -> 2 | B82: Μοσχάρι με μαύρη μπύρα | C82: Ελαιόλαδο | D82: =IF(C82<>"",INDEX(Υλικά!$D$3:$D$130,MATCH(C82,Υλικά!$B$3:$B$130,0),1),"") -> gr | E82: 100 | F82: =IF(C82<>"",$E82*INDEX(Υλικά!$G$3:$G$130,MATCH($C82,Υλικά!$B$3:$B$130,0),1)/INDEX(Υλικά!$E$3:$E$130,MATCH($C82,Υλικά!$B$3:$B$130,0),1),0) -> 0 | G82: =IF(C82<>"",$E82*INDEX(Υλικά!$H$3:$H$130,MATCH($C82,Υλικά!$B$3:$B$130,0),1)/INDEX(Υλικά!$E$3:$E$130,MATCH($C82,Υλικά!$B$3:$B$130,0),1),0) -> 0 | H82: =IF(C82<>"",$E82*INDEX(Υλικά!$I$3:$I$130,MATCH($C82,Υλικά!$B$3:$B$130,0),1)/INDEX(Υλικά!$E$3:$E$130,MATCH($C82,Υλικά!$B$3:$B$130,0),1),0) -> 93.3 | I82: =$F82*Ref!$B$2 -> 0 | J82: =$G82*Ref!$B$3 -> 0 | K82: =$H82*Ref!$B$4 -> 839.7 | L82: =SUM(I82:K82) -> 839.7
A83: =IF($B83<>"",IF($B83<>$B82,1,$A82+1),"") -> 3 | B83: Μοσχάρι με μαύρη μπύρα | C83: Μπύρα 6% | D83: =IF(C83<>"",INDEX(Υλικά!$D$3:$D$130,MATCH(C83,Υλικά!$B$3:$B$130,0),1),"") -> gr | E83: 1332 | F83: =IF(C83<>"",$E83*INDEX(Υλικά!$G$3:$G$130,MATCH($C83,Υλικά!$B$3:$B$130,0),1)/INDEX(Υλικά!$E$3:$E$130,MATCH($C83,Υλικά!$B$3:$B$130,0),1),0) -> 6.66 | G83: =IF(C83<>"",$E83*INDEX(Υλικά!$H$3:$H$130,MATCH($C83,Υλικά!$B$3:$B$130,0),1)/INDEX(Υλικά!$E$3:$E$130,MATCH($C83,Υλικά!$B$3:$B$130,0),1),0) -> 47.952 | H83: =IF(C83<>"",$E83*INDEX(Υλικά!$I$3:$I$130,MATCH($C83,Υλικά!$B$3:$B$130,0),1)/INDEX(Υλικά!$E$3:$E$130,MATCH($C83,Υλικά!$B$3:$B$130,0),1),0) -> 0 | I83: =$F83*Ref!$B$2 -> 26.64 | J83: =$G83*Ref!$B$3 -> 191.808 | K83: =$H83*Ref!$B$4 -> 0 | L83: =SUM(I83:K83) -> 218.448
A84: =IF($B84<>"",IF($B84<>$B83,1,$A83+1),"") -> 4 | B84: Μοσχάρι με μαύρη μπύρα | C84: Κρεμμύδι | D84: =IF(C84<>"",INDEX(Υλικά!$D$3:$D$130,MATCH(C84,Υλικά!$B$3:$B$130,0),1),"") -> gr | E84: 750 | F84: =IF(C84<>"",$E84*INDEX(Υλικά!$G$3:$G$130,MATCH($C84,Υλικά!$B$3:$B$130,0),1)/INDEX(Υλικά!$E$3:$E$130,MATCH($C84,Υλικά!$B$3:$B$130,0),1),0) -> 8.25 | G84: =IF(C84<>"",$E84*INDEX(Υλικά!$H$3:$H$130,MATCH($C84,Υλικά!$B$3:$B$130,0),1)/INDEX(Υλικά!$E$3:$E$130,MATCH($C84,Υλικά!$B$3:$B$130,0),1),0) -> 69.75 | H84: =IF(C84<>"",$E84*INDEX(Υλικά!$I$3:$I$130,MATCH($C84,Υλικά!$B$3:$B$130,0),1)/INDEX(Υλικά!$E$3:$E$130,MATCH($C84,Υλικά!$B$3:$B$130,0),1),0) -> 0.75 | I84: =$F84*Ref!$B$2 -> 33 | J84: =$G84*Ref!$B$3 -> 279 | K84: =$H84*Ref!$B$4 -> 6.75 | L84: =SUM(I84:K84) -> 318.75
A85: =IF($B85<>"",IF($B85<>$B84,1,$A84+1),"") -> 5 | B85: Μοσχάρι με μαύρη μπύρα | C85: Καρότα | D85: =IF(C85<>"",INDEX(Υλικά!$D$3:$D$130,MATCH(C85,Υλικά!$B$3:$B$130,0),1),"") -> gr | E85: 200 | F85: =IF(C85<>"",$E85*INDEX(Υλικά!$G$3:$G$130,MATCH($C85,Υλικά!$B$3:$B$130,0),1)/INDEX(Υλικά!$E$3:$E$130,MATCH($C85,Υλικά!$B$3:$B$130,0),1),0) -> 2.2 | G85: =IF(C85<>"",$E85*INDEX(Υλικά!$H$3:$H$130,MATCH($C85,Υλικά!$B$3:$B$130,0),1)/INDEX(Υλικά!$E$3:$E$130,MATCH($C85,Υλικά!$B$3:$B$130,0),1),0) -> 19.4 | H85: =IF(C85<>"",$E85*INDEX(Υλικά!$I$3:$I$130,MATCH($C85,Υλικά!$B$3:$B$130,0),1)/INDEX(Υλικά!$E$3:$E$130,MATCH($C85,Υλικά!$B$3:$B$130,0),1),0) -> 0.4 | I85: =$F85*Ref!$B$2 -> 8.8 | J85: =$G85*Ref!$B$3 -> 77.6 | K85: =$H85*Ref!$B$4 -> 3.6 | L85: =SUM(I85:K85) -> 90
A86: =IF($B86<>"",IF($B86<>$B85,1,$A85+1),"") -> 6 | B86: Μοσχάρι με μαύρη μπύρα | C86: Μήλο | D86: =IF(C86<>"",INDEX(Υλικά!$D$3:$D$130,MATCH(C86,Υλικά!$B$3:$B$130,0),1),"") -> gr | E86: 700 | F86: =IF(C86<>"",$E86*INDEX(Υλικά!$G$3:$G$130,MATCH($C86,Υλικά!$B$3:$B$130,0),1)/INDEX(Υλικά!$E$3:$E$130,MATCH($C86,Υλικά!$B$3:$B$130,0),1),0) -> 2.1 | G86: =IF(C86<>"",$E86*INDEX(Υλικά!$H$3:$H$130,MATCH($C86,Υλικά!$B$3:$B$130,0),1)/INDEX(Υλικά!$E$3:$E$130,MATCH($C86,Υλικά!$B$3:$B$130,0),1),0) -> 98 | H86: =IF(C86<>"",$E86*INDEX(Υλικά!$I$3:$I$130,MATCH($C86,Υλικά!$B$3:$B$130,0),1)/INDEX(Υλικά!$E$3:$E$130,MATCH($C86,Υλικά!$B$3:$B$130,0),1),0) -> 1.4 | I86: =$F86*Ref!$B$2 -> 8.4 | J86: =$G86*Ref!$B$3 -> 392 | K86: =$H86*Ref!$B$4 -> 12.6 | L86: =SUM(I86:K86) -> 413 | M86: =SUM(L81:L86) -> 4147.898
A87: =IF($B87<>"",IF($B87<>$B86,1,$A86+1),"") -> 1 | B87: Βραδινό γιαούρτι-φρούτα | C87: Γιαούρτι Όλυμπος 2% | D87: =IF(C87<>"",INDEX(Υλικά!$D$3:$D$130,MATCH(C87,Υλικά!$B$3:$B$130,0),1),"") -> gr | E87: 200 | F87: =IF(C87<>"",$E87*INDEX(Υλικά!$G$3:$G$130,MATCH($C87,Υλικά!$B$3:$B$130,0),1)/INDEX(Υλικά!$E$3:$E$130,MATCH($C87,Υλικά!$B$3:$B$130,0),1),0) -> 16 | G87: =IF(C87<>"",$E87*INDEX(Υλικά!$H$3:$H$130,MATCH($C87,Υλικά!$B$3:$B$130,0),1)/INDEX(Υλικά!$E$3:$E$130,MATCH($C87,Υλικά!$B$3:$B$130,0),1),0) -> 8 | H87: =IF(C87<>"",$E87*INDEX(Υλικά!$I$3:$I$130,MATCH($C87,Υλικά!$B$3:$B$130,0),1)/INDEX(Υλικά!$E$3:$E$130,MATCH($C87,Υλικά!$B$3:$B$130,0),1),0) -> 4 | I87: =$F87*Ref!$B$2 -> 64 | J87: =$G87*Ref!$B$3 -> 32 | K87: =$H87*Ref!$B$4 -> 36 | L87: =SUM(I87:K87) -> 132
A88: =IF($B88<>"",IF($B88<>$B87,1,$A87+1),"") -> 2 | B88: Βραδινό γιαούρτι-φρούτα | C88: Βρώμη Quaker | D88: =IF(C88<>"",INDEX(Υλικά!$D$3:$D$130,MATCH(C88,Υλικά!$B$3:$B$130,0),1),"") -> gr | E88: 10 | F88: =IF(C88<>"",$E88*INDEX(Υλικά!$G$3:$G$130,MATCH($C88,Υλικά!$B$3:$B$130,0),1)/INDEX(Υλικά!$E$3:$E$130,MATCH($C88,Υλικά!$B$3:$B$130,0),1),0) -> 1.1 | G88: =IF(C88<>"",$E88*INDEX(Υλικά!$H$3:$H$130,MATCH($C88,Υλικά!$B$3:$B$130,0),1)/INDEX(Υλικά!$E$3:$E$130,MATCH($C88,Υλικά!$B$3:$B$130,0),1),0) -> 6 | H88: =IF(C88<>"",$E88*INDEX(Υλικά!$I$3:$I$130,MATCH($C88,Υλικά!$B$3:$B$130,0),1)/INDEX(Υλικά!$E$3:$E$130,MATCH($C88,Υλικά!$B$3:$B$130,0),1),0) -> 0.8 | I88: =$F88*Ref!$B$2 -> 4.4 | J88: =$G88*Ref!$B$3 -> 24 | K88: =$H88*Ref!$B$4 -> 7.2 | L88: =SUM(I88:K88) -> 35.6
A89: =IF($B89<>"",IF($B89<>$B88,1,$A88+1),"") -> 3 | B89: Βραδινό γιαούρτι-φρούτα | C89: Μήλο | D89: =IF(C89<>"",INDEX(Υλικά!$D$3:$D$130,MATCH(C89,Υλικά!$B$3:$B$130,0),1),"") -> gr | E89: 200 | F89: =IF(C89<>"",$E89*INDEX(Υλικά!$G$3:$G$130,MATCH($C89,Υλικά!$B$3:$B$130,0),1)/INDEX(Υλικά!$E$3:$E$130,MATCH($C89,Υλικά!$B$3:$B$130,0),1),0) -> 0.6 | G89: =IF(C89<>"",$E89*INDEX(Υλικά!$H$3:$H$130,MATCH($C89,Υλικά!$B$3:$B$130,0),1)/INDEX(Υλικά!$E$3:$E$130,MATCH($C89,Υλικά!$B$3:$B$130,0),1),0) -> 28 | H89: =IF(C89<>"",$E89*INDEX(Υλικά!$I$3:$I$130,MATCH($C89,Υλικά!$B$3:$B$130,0),1)/INDEX(Υλικά!$E$3:$E$130,MATCH($C89,Υλικά!$B$3:$B$130,0),1),0) -> 0.4 | I89: =$F89*Ref!$B$2 -> 2.4 | J89: =$G89*Ref!$B$3 -> 112 | K89: =$H89*Ref!$B$4 -> 3.6 | L89: =SUM(I89:K89) -> 118
A90: =IF($B90<>"",IF($B90<>$B89,1,$A89+1),"") -> 4 | B90: Βραδινό γιαούρτι-φρούτα | C90: Μαντερίνι | D90: =IF(C90<>"",INDEX(Υλικά!$D$3:$D$130,MATCH(C90,Υλικά!$B$3:$B$130,0),1),"") -> gr | E90: 80 | F90: =IF(C90<>"",$E90*INDEX(Υλικά!$G$3:$G$130,MATCH($C90,Υλικά!$B$3:$B$130,0),1)/INDEX(Υλικά!$E$3:$E$130,MATCH($C90,Υλικά!$B$3:$B$130,0),1),0) -> 0.64 | G90: =IF(C90<>"",$E90*INDEX(Υλικά!$H$3:$H$130,MATCH($C90,Υλικά!$B$3:$B$130,0),1)/INDEX(Υλικά!$E$3:$E$130,MATCH($C90,Υλικά!$B$3:$B$130,0),1),0) -> 10.4 | H90: =IF(C90<>"",$E90*INDEX(Υλικά!$I$3:$I$130,MATCH($C90,Υλικά!$B$3:$B$130,0),1)/INDEX(Υλικά!$E$3:$E$130,MATCH($C90,Υλικά!$B$3:$B$130,0),1),0) -> 0.24 | I90: =$F90*Ref!$B$2 -> 2.56 | J90: =$G90*Ref!$B$3 -> 41.6 | K90: =$H90*Ref!$B$4 -> 2.16 | L90: =SUM(I90:K90) -> 46.32
A91: =IF($B91<>"",IF($B91<>$B90,1,$A90+1),"") -> 5 | B91: Βραδινό γιαούρτι-φρούτα | C91: Μπανάνα | D91: =IF(C91<>"",INDEX(Υλικά!$D$3:$D$130,MATCH(C91,Υλικά!$B$3:$B$130,0),1),"") -> gr | E91: 100 | F91: =IF(C91<>"",$E91*INDEX(Υλικά!$G$3:$G$130,MATCH($C91,Υλικά!$B$3:$B$130,0),1)/INDEX(Υλικά!$E$3:$E$130,MATCH($C91,Υλικά!$B$3:$B$130,0),1),0) -> 1.1 | G91: =IF(C91<>"",$E91*INDEX(Υλικά!$H$3:$H$130,MATCH($C91,Υλικά!$B$3:$B$130,0),1)/INDEX(Υλικά!$E$3:$E$130,MATCH($C91,Υλικά!$B$3:$B$130,0),1),0) -> 22.8 | H91: =IF(C91<>"",$E91*INDEX(Υλικά!$I$3:$I$130,MATCH($C91,Υλικά!$B$3:$B$130,0),1)/INDEX(Υλικά!$E$3:$E$130,MATCH($C91,Υλικά!$B$3:$B$130,0),1),0) -> 0.3 | I91: =$F91*Ref!$B$2 -> 4.4 | J91: =$G91*Ref!$B$3 -> 91.2 | K91: =$H91*Ref!$B$4 -> 2.7 | L91: =SUM(I91:K91) -> 98.3
...

Sheet ΣυνδΑθρ
A1: Συνδυασμός | B1: Prot gr | C1: Carb gr | D1: Fat gr | E1: Prot Kcal | F1: Carb Kcal | G1: Fat Kcal | H1: Sum Kcal | I1: Μονάδα | J1: Βάρος gr | K1: Μερίδες
A2: {=IFERROR(INDEX(Συνδυασμοί!$B$2:$B$998, MATCH(0,COUNTIF($A$1:$A1, Συνδυασμοί!$B$2:$B$998),0)),"")} -> Μελιτζανοπίλαφο | B2: =SUMIF(Συνδυασμοί!$B$2:$B$998,$A2,Συνδυασμοί!$F$2:$F$998) -> 33.3 | C2: =SUMIF(Συνδυασμοί!$B$2:$B$998,$A2,Συνδυασμοί!$G$2:$G$998) -> 255.45 | D2: =SUMIF(Συνδυασμοί!$B$2:$B$998,$A2,Συνδυασμοί!$H$2:$H$998) -> 51.09 | E2: =Ref!$B$2*$B2 -> 133.2 | F2: =Ref!$B$3*$C2 -> 1021.8 | G2: =Ref!$B$4*$D2 -> 459.81 | H2: =SUM($E2:$G2) -> 1614.81 | I2: gr | J2: 1600 | K2: 4
A3: {=IFERROR(INDEX(Συνδυασμοί!$B$2:$B$998, MATCH(0,COUNTIF($A$1:$A2, Συνδυασμοί!$B$2:$B$998),0)),"")} -> Χωριάτικη Σαλάτα | B3: =SUMIF(Συνδυασμοί!$B$2:$B$998,$A3,Συνδυασμοί!$F$2:$F$998) -> 13.11 | C3: =SUMIF(Συνδυασμοί!$B$2:$B$998,$A3,Συνδυασμοί!$G$2:$G$998) -> 24.55 | D3: =SUMIF(Συνδυασμοί!$B$2:$B$998,$A3,Συνδυασμοί!$H$2:$H$998) -> 27.63 | E3: =Ref!$B$2*$B3 -> 52.44 | F3: =Ref!$B$3*$C3 -> 98.2 | G3: =Ref!$B$4*$D3 -> 248.67 | H3: =SUM($E3:$G3) -> 399.31 | I3: pc | J3: 1 | K3: 1
A4: {=IFERROR(INDEX(Συνδυασμοί!$B$2:$B$998, MATCH(0,COUNTIF($A$1:$A3, Συνδυασμοί!$B$2:$B$998),0)),"")} -> Πρωινό Γάλα-Τοστ | B4: =SUMIF(Συνδυασμοί!$B$2:$B$998,$A4,Συνδυασμοί!$F$2:$F$998) -> 23.3 | C4: =SUMIF(Συνδυασμοί!$B$2:$B$998,$A4,Συνδυασμοί!$G$2:$G$998) -> 36.5 | D4: =SUMIF(Συνδυασμοί!$B$2:$B$998,$A4,Συνδυασμοί!$H$2:$H$998) -> 11.6 | E4: =Ref!$B$2*$B4 -> 93.2 | F4: =Ref!$B$3*$C4 -> 146 | G4: =Ref!$B$4*$D4 -> 104.4 | H4: =SUM($E4:$G4) -> 343.6 | I4: pc | J4: 1 | K4: 1
A5: {=IFERROR(INDEX(Συνδυασμοί!$B$2:$B$998, MATCH(0,COUNTIF($A$1:$A4, Συνδυασμοί!$B$2:$B$998),0)),"")} -> Πρωινό ΠαξιμΚυθ-Φέτα | B5: =SUMIF(Συνδυασμοί!$B$2:$B$998,$A5,Συνδυασμοί!$F$2:$F$998) -> 16.86 | C5: =SUMIF(Συνδυασμοί!$B$2:$B$998,$A5,Συνδυασμοί!$G$2:$G$998) -> 42.12 | D5: =SUMIF(Συνδυασμοί!$B$2:$B$998,$A5,Συνδυασμοί!$H$2:$H$998) -> 22.62 | E5: =Ref!$B$2*$B5 -> 67.44 | F5: =Ref!$B$3*$C5 -> 168.48 | G5: =Ref!$B$4*$D5 -> 203.58 | H5: =SUM($E5:$G5) -> 439.5 | I5: pc | J5: 1 | K5: 1
A6: {=IFERROR(INDEX(Συνδυασμοί!$B$2:$B$998, MATCH(0,COUNTIF($A$1:$A5, Συνδυασμοί!$B$2:$B$998),0)),"")} -> Πρωινό Αυγά | B6: =SUMIF(Συνδυασμοί!$B$2:$B$998,$A6,Συνδυασμοί!$F$2:$F$998) -> 34.6 | C6: =SUMIF(Συνδυασμοί!$B$2:$B$998,$A6,Συνδυασμοί!$G$2:$G$998) -> 37.72 | D6: =SUMIF(Συνδυασμοί!$B$2:$B$998,$A6,Συνδυασμοί!$H$2:$H$998) -> 24.866 | E6: =Ref!$B$2*$B6 -> 138.4 | F6: =Ref!$B$3*$C6 -> 150.88 | G6: =Ref!$B$4*$D6 -> 223.794 | H6: =SUM($E6:$G6) -> 513.074 | I6: pc | J6: 1 | K6: 1
A7: {=IFERROR(INDEX(Συνδυασμοί!$B$2:$B$998, MATCH(0,COUNTIF($A$1:$A6, Συνδυασμοί!$B$2:$B$998),0)),"")} -> Μοσχάρι με Πιπεριές Πιλάφι | B7: =SUMIF(Συνδυασμοί!$B$2:$B$998,$A7,Συνδυασμοί!$F$2:$F$998) -> 163.08 | C7: =SUMIF(Συνδυασμοί!$B$2:$B$998,$A7,Συνδυασμοί!$G$2:$G$998) -> 143.04 | D7: =SUMIF(Συνδυασμοί!$B$2:$B$998,$A7,Συνδυασμοί!$H$2:$H$998) -> 78.29 | E7: =Ref!$B$2*$B7 -> 652.32 | F7: =Ref!$B$3*$C7 -> 572.16 | G7: =Ref!$B$4*$D7 -> 704.61 | H7: =SUM($E7:$G7) -> 1929.09 | I7: gr | J7: 1800 | K7: 5
A8: {=IFERROR(INDEX(Συνδυασμοί!$B$2:$B$998, MATCH(0,COUNTIF($A$1:$A7, Συνδυασμοί!$B$2:$B$998),0)),"")} -> Κοτόπουλο Κόρμα | B8: =SUMIF(Συνδυασμοί!$B$2:$B$998,$A8,Συνδυασμοί!$F$2:$F$998) -> 268.5 | C8: =SUMIF(Συνδυασμοί!$B$2:$B$998,$A8,Συνδυασμοί!$G$2:$G$998) -> 49.1 | D8: =SUMIF(Συνδυασμοί!$B$2:$B$998,$A8,Συνδυασμοί!$H$2:$H$998) -> 113.09 | E8: =Ref!$B$2*$B8 -> 1074 | F8: =Ref!$B$3*$C8 -> 196.4 | G8: =Ref!$B$4*$D8 -> 1017.81 | H8: =SUM($E8:$G8) -> 2288.21 | I8: gr
